Workbook

Sheet NLZ NAP Report
A1: NAP REPORT | H1: NAP REPORT
A2: AREA | B2: PROVINCE | C2: <24HOURS | D2: 1-3 DAYS | E2: >3DAYS | F2: TOTAL | H2: AREA | I2: PROVINCE | J2: <24HOURS | K2: 1-3 DAYS | L2: >3DAYS | M2: TOTAL
A3: Cluster 1 | B3: Pangasinan | C3: =COUNTIFS('2025 NAP'!$D:$D, UPPER($B3), '2025 NAP'!$X:$X, "<1") -> 8 | D3: =COUNTIFS('2025 NAP'!$D:$D, UPPER($B3), '2025 NAP'!$X:$X, ">=1", '2025 NAP'!$X:$X, "<=3") -> 1 | E3: =COUNTIFS('2025 NAP'!$D:$D, UPPER($B3), '2025 NAP'!$X:$X, ">3") -> 9 | F3: =COUNTIF('2025 NAP'!D:D,B3) -> 18 | H3: =IFERROR(__xludf.DUMMYFUNCTION("{ SORT(FILTER(A3:F18, F3:F18 > 0), 6, FALSE); {""TOTAL"", """", SUM(C3:C18), SUM(D3:D18), SUM(E3:E18), SUM(F3:F18)} }"),"Cluster 1") -> Cluster 1 | I3: =IFERROR(__xludf.DUMMYFUNCTION("""COMPUTED_VALUE"""),"Pangasinan") -> Pangasinan | J3: =IFERROR(__xludf.DUMMYFUNCTION("""COMPUTED_VALUE"""),8.0) -> 8 | K3: =IFERROR(__xludf.DUMMYFUNCTION("""COMPUTED_VALUE"""),1.0) -> 1 | L3: =IFERROR(__xludf.DUMMYFUNCTION("""COMPUTED_VALUE"""),9.0) -> 9 | M3: =IFERROR(__xludf.DUMMYFUNCTION("""COMPUTED_VALUE"""),18.0) -> 18
A4: Cluster 3 | B4: Nueva_Ecija | C4: =COUNTIFS('2025 NAP'!$D:$D, UPPER($B4), '2025 NAP'!$X:$X, "<1") -> 5 | D4: =COUNTIFS('2025 NAP'!$D:$D, UPPER($B4), '2025 NAP'!$X:$X, ">=1", '2025 NAP'!$X:$X, "<=3") -> 2 | E4: =COUNTIFS('2025 NAP'!$D:$D, UPPER($B4), '2025 NAP'!$X:$X, ">3") -> 0 | F4: =COUNTIF('2025 NAP'!D:D,B4) -> 7 | H4: =IFERROR(__xludf.DUMMYFUNCTION("""COMPUTED_VALUE"""),"Cluster 3") -> Cluster 3 | I4: =IFERROR(__xludf.DUMMYFUNCTION("""COMPUTED_VALUE"""),"Nueva_Vizcaya") -> Nueva_Vizcaya | J4: =IFERROR(__xludf.DUMMYFUNCTION("""COMPUTED_VALUE"""),1.0) -> 1 | K4: =IFERROR(__xludf.DUMMYFUNCTION("""COMPUTED_VALUE"""),11.0) -> 11 | L4: =IFERROR(__xludf.DUMMYFUNCTION("""COMPUTED_VALUE"""),1.0) -> 1 | M4: =IFERROR(__xludf.DUMMYFUNCTION("""COMPUTED_VALUE"""),13.0) -> 13
A5: Cluster 2 | B5: Benguet | C5: =COUNTIFS('2025 NAP'!$D:$D, UPPER($B5), '2025 NAP'!$X:$X, "<1") -> 0 | D5: =COUNTIFS('2025 NAP'!$D:$D, UPPER($B5), '2025 NAP'!$X:$X, ">=1", '2025 NAP'!$X:$X, "<=3") -> 0 | E5: =COUNTIFS('2025 NAP'!$D:$D, UPPER($B5), '2025 NAP'!$X:$X, ">3") -> 3 | F5: =COUNTIF('2025 NAP'!D:D,B5) -> 3 | H5: =IFERROR(__xludf.DUMMYFUNCTION("""COMPUTED_VALUE"""),"Cluster 2") -> Cluster 2 | I5: =IFERROR(__xludf.DUMMYFUNCTION("""COMPUTED_VALUE"""),"Ilocos_Sur") -> Ilocos_Sur | J5: =IFERROR(__xludf.DUMMYFUNCTION("""COMPUTED_VALUE"""),7.0) -> 7 | K5: =IFERROR(__xludf.DUMMYFUNCTION("""COMPUTED_VALUE"""),3.0) -> 3 | L5: =IFERROR(__xludf.DUMMYFUNCTION("""COMPUTED_VALUE"""),0.0) -> 0 | M5: =IFERROR(__xludf.DUMMYFUNCTION("""COMPUTED_VALUE"""),10.0) -> 10
A6: Cluster 2 | B6: La_Union | C6: =COUNTIFS('2025 NAP'!$D:$D, UPPER($B6), '2025 NAP'!$X:$X, "<1") -> 1 | D6: =COUNTIFS('2025 NAP'!$D:$D, UPPER($B6), '2025 NAP'!$X:$X, ">=1", '2025 NAP'!$X:$X, "<=3") -> 2 | E6: =COUNTIFS('2025 NAP'!$D:$D, UPPER($B6), '2025 NAP'!$X:$X, ">3") -> 1 | F6: =COUNTIF('2025 NAP'!D:D,B6) -> 4 | H6: =IFERROR(__xludf.DUMMYFUNCTION("""COMPUTED_VALUE"""),"Cluster 3") -> Cluster 3 | I6: =IFERROR(__xludf.DUMMYFUNCTION("""COMPUTED_VALUE"""),"Nueva_Ecija") -> Nueva_Ecija | J6: =IFERROR(__xludf.DUMMYFUNCTION("""COMPUTED_VALUE"""),5.0) -> 5 | K6: =IFERROR(__xludf.DUMMYFUNCTION("""COMPUTED_VALUE"""),2.0) -> 2 | L6: =IFERROR(__xludf.DUMMYFUNCTION("""COMPUTED_VALUE"""),0.0) -> 0 | M6: =IFERROR(__xludf.DUMMYFUNCTION("""COMPUTED_VALUE"""),7.0) -> 7
A7: Cluster 2 | B7: Abra | C7: =COUNTIFS('2025 NAP'!$D:$D, UPPER($B7), '2025 NAP'!$X:$X, "<1") -> 0 | D7: =COUNTIFS('2025 NAP'!$D:$D, UPPER($B7), '2025 NAP'!$X:$X, ">=1", '2025 NAP'!$X:$X, "<=3") -> 0 | E7: =COUNTIFS('2025 NAP'!$D:$D, UPPER($B7), '2025 NAP'!$X:$X, ">3") -> 0 | F7: =COUNTIF('2025 NAP'!D:D,B7) -> 0 | H7: =IFERROR(__xludf.DUMMYFUNCTION("""COMPUTED_VALUE"""),"Cluster 2") -> Cluster 2 | I7: =IFERROR(__xludf.DUMMYFUNCTION("""COMPUTED_VALUE"""),"Ilocos_Norte") -> Ilocos_Norte | J7: =IFERROR(__xludf.DUMMYFUNCTION("""COMPUTED_VALUE"""),5.0) -> 5 | K7: =IFERROR(__xludf.DUMMYFUNCTION("""COMPUTED_VALUE"""),0.0) -> 0 | L7: =IFERROR(__xludf.DUMMYFUNCTION("""COMPUTED_VALUE"""),0.0) -> 0 | M7: =IFERROR(__xludf.DUMMYFUNCTION("""COMPUTED_VALUE"""),5.0) -> 5
A8: Cluster 2 | B8: Ilocos_Norte | C8: =COUNTIFS('2025 NAP'!$D:$D, UPPER($B8), '2025 NAP'!$X:$X, "<1") -> 5 | D8: =COUNTIFS('2025 NAP'!$D:$D, UPPER($B8), '2025 NAP'!$X:$X, ">=1", '2025 NAP'!$X:$X, "<=3") -> 0 | E8: =COUNTIFS('2025 NAP'!$D:$D, UPPER($B8), '2025 NAP'!$X:$X, ">3") -> 0 | F8: =COUNTIF('2025 NAP'!D:D,B8) -> 5 | H8: =IFERROR(__xludf.DUMMYFUNCTION("""COMPUTED_VALUE"""),"Cluster 3") -> Cluster 3 | I8: =IFERROR(__xludf.DUMMYFUNCTION("""COMPUTED_VALUE"""),"Cagayan") -> Cagayan | J8: =IFERROR(__xludf.DUMMYFUNCTION("""COMPUTED_VALUE"""),4.0) -> 4 | K8: =IFERROR(__xludf.DUMMYFUNCTION("""COMPUTED_VALUE"""),0.0) -> 0 | L8: =IFERROR(__xludf.DUMMYFUNCTION("""COMPUTED_VALUE"""),1.0) -> 1 | M8: =IFERROR(__xludf.DUMMYFUNCTION("""COMPUTED_VALUE"""),5.0) -> 5
A9: Cluster 2 | B9: Mt_Province | C9: =COUNTIFS('2025 NAP'!$D:$D, UPPER($B9), '2025 NAP'!$X:$X, "<1") -> 0 | D9: =COUNTIFS('2025 NAP'!$D:$D, UPPER($B9), '2025 NAP'!$X:$X, ">=1", '2025 NAP'!$X:$X, "<=3") -> 0 | E9: =COUNTIFS('2025 NAP'!$D:$D, UPPER($B9), '2025 NAP'!$X:$X, ">3") -> 0 | F9: =COUNTIF('2025 NAP'!D:D,B9) -> 0 | H9: =IFERROR(__xludf.DUMMYFUNCTION("""COMPUTED_VALUE"""),"Cluster 2") -> Cluster 2 | I9: =IFERROR(__xludf.DUMMYFUNCTION("""COMPUTED_VALUE"""),"La_Union") -> La_Union | J9: =IFERROR(__xludf.DUMMYFUNCTION("""COMPUTED_VALUE"""),1.0) -> 1 | K9: =IFERROR(__xludf.DUMMYFUNCTION("""COMPUTED_VALUE"""),2.0) -> 2 | L9: =IFERROR(__xludf.DUMMYFUNCTION("""COMPUTED_VALUE"""),1.0) -> 1 | M9: =IFERROR(__xludf.DUMMYFUNCTION("""COMPUTED_VALUE"""),4.0) -> 4
A10: Cluster 3 | B10: Nueva_Vizcaya | C10: =COUNTIFS('2025 NAP'!$D:$D, UPPER($B10), '2025 NAP'!$X:$X, "<1") -> 1 | D10: =COUNTIFS('2025 NAP'!$D:$D, UPPER($B10), '2025 NAP'!$X:$X, ">=1", '2025 NAP'!$X:$X, "<=3") -> 11 | E10: =COUNTIFS('2025 NAP'!$D:$D, UPPER($B10), '2025 NAP'!$X:$X, ">3") -> 1 | F10: =COUNTIF('2025 NAP'!D:D,B10) -> 13 | H10: =IFERROR(__xludf.DUMMYFUNCTION("""COMPUTED_VALUE"""),"Cluster 3") -> Cluster 3 | I10: =IFERROR(__xludf.DUMMYFUNCTION("""COMPUTED_VALUE"""),"Isabela") -> Isabela | J10: =IFERROR(__xludf.DUMMYFUNCTION("""COMPUTED_VALUE"""),0.0) -> 0 | K10: =IFERROR(__xludf.DUMMYFUNCTION("""COMPUTED_VALUE"""),4.0) -> 4 | L10: =IFERROR(__xludf.DUMMYFUNCTION("""COMPUTED_VALUE"""),0.0) -> 0 | M10: =IFERROR(__xludf.DUMMYFUNCTION("""COMPUTED_VALUE"""),4.0) -> 4
A11: Cluster 3 | B11: Cagayan | C11: =COUNTIFS('2025 NAP'!$D:$D, UPPER($B11), '2025 NAP'!$X:$X, "<1") -> 4 | D11: =COUNTIFS('2025 NAP'!$D:$D, UPPER($B11), '2025 NAP'!$X:$X, ">=1", '2025 NAP'!$X:$X, "<=3") -> 0 | E11: =COUNTIFS('2025 NAP'!$D:$D, UPPER($B11), '2025 NAP'!$X:$X, ">3") -> 1 | F11: =COUNTIF('2025 NAP'!D:D,B11) -> 5 | H11: =IFERROR(__xludf.DUMMYFUNCTION("""COMPUTED_VALUE"""),"Cluster 2") -> Cluster 2 | I11: =IFERROR(__xludf.DUMMYFUNCTION("""COMPUTED_VALUE"""),"Benguet") -> Benguet | J11: =IFERROR(__xludf.DUMMYFUNCTION("""COMPUTED_VALUE"""),0.0) -> 0 | K11: =IFERROR(__xludf.DUMMYFUNCTION("""COMPUTED_VALUE"""),0.0) -> 0 | L11: =IFERROR(__xludf.DUMMYFUNCTION("""COMPUTED_VALUE"""),3.0) -> 3 | M11: =IFERROR(__xludf.DUMMYFUNCTION("""COMPUTED_VALUE"""),3.0) -> 3
A12: Cluster 2 | B12: Ilocos_Sur | C12: =COUNTIFS('2025 NAP'!$D:$D, UPPER($B12), '2025 NAP'!$X:$X, "<1") -> 7 | D12: =COUNTIFS('2025 NAP'!$D:$D, UPPER($B12), '2025 NAP'!$X:$X, ">=1", '2025 NAP'!$X:$X, "<=3") -> 3 | E12: =COUNTIFS('2025 NAP'!$D:$D, UPPER($B12), '2025 NAP'!$X:$X, ">3") -> 0 | F12: =COUNTIF('2025 NAP'!D:D,B12) -> 10 | H12: =IFERROR(__xludf.DUMMYFUNCTION("""COMPUTED_VALUE"""),"Cluster 3") -> Cluster 3 | I12: =IFERROR(__xludf.DUMMYFUNCTION("""COMPUTED_VALUE"""),"Apayao") -> Apayao | J12: =IFERROR(__xludf.DUMMYFUNCTION("""COMPUTED_VALUE"""),1.0) -> 1 | K12: =IFERROR(__xludf.DUMMYFUNCTION("""COMPUTED_VALUE"""),0.0) -> 0 | L12: =IFERROR(__xludf.DUMMYFUNCTION("""COMPUTED_VALUE"""),0.0) -> 0 | M12: =IFERROR(__xludf.DUMMYFUNCTION("""COMPUTED_VALUE"""),1.0) -> 1
A13: Cluster 3 | B13: Isabela | C13: =COUNTIFS('2025 NAP'!$D:$D, UPPER($B13), '2025 NAP'!$X:$X, "<1") -> 0 | D13: =COUNTIFS('2025 NAP'!$D:$D, UPPER($B13), '2025 NAP'!$X:$X, ">=1", '2025 NAP'!$X:$X, "<=3") -> 4 | E13: =COUNTIFS('2025 NAP'!$D:$D, UPPER($B13), '2025 NAP'!$X:$X, ">3") -> 0 | F13: =COUNTIF('2025 NAP'!D:D,B13) -> 4 | H13: =IFERROR(__xludf.DUMMYFUNCTION("""COMPUTED_VALUE"""),"Cluster 3") -> Cluster 3 | I13: =IFERROR(__xludf.DUMMYFUNCTION("""COMPUTED_VALUE"""),"Ifugao") -> Ifugao | J13: =IFERROR(__xludf.DUMMYFUNCTION("""COMPUTED_VALUE"""),0.0) -> 0 | K13: =IFERROR(__xludf.DUMMYFUNCTION("""COMPUTED_VALUE"""),1.0) -> 1 | L13: =IFERROR(__xludf.DUMMYFUNCTION("""COMPUTED_VALUE"""),0.0) -> 0 | M13: =IFERROR(__xludf.DUMMYFUNCTION("""COMPUTED_VALUE"""),1.0) -> 1
A14: Cluster 3 | B14: Apayao | C14: =COUNTIFS('2025 NAP'!$D:$D, UPPER($B14), '2025 NAP'!$X:$X, "<1") -> 1 | D14: =COUNTIFS('2025 NAP'!$D:$D, UPPER($B14), '2025 NAP'!$X:$X, ">=1", '2025 NAP'!$X:$X, "<=3") -> 0 | E14: =COUNTIFS('2025 NAP'!$D:$D, UPPER($B14), '2025 NAP'!$X:$X, ">3") -> 0 | F14: =COUNTIF('2025 NAP'!D:D,B14) -> 1 | H14: =IFERROR(__xludf.DUMMYFUNCTION("""COMPUTED_VALUE"""),"TOTAL") -> TOTAL | I14: =IFERROR(__xludf.DUMMYFUNCTION("""COMPUTED_VALUE"""),"") | J14: =IFERROR(__xludf.DUMMYFUNCTION("""COMPUTED_VALUE"""),32.0) -> 32 | K14: =IFERROR(__xludf.DUMMYFUNCTION("""COMPUTED_VALUE"""),24.0) -> 24 | L14: =IFERROR(__xludf.DUMMYFUNCTION("""COMPUTED_VALUE"""),15.0) -> 15 | M14: =IFERROR(__xludf.DUMMYFUNCTION("""COMPUTED_VALUE"""),71.0) -> 71
A15: Cluster 3 | B15: Ifugao | C15: =COUNTIFS('2025 NAP'!$D:$D, UPPER($B15), '2025 NAP'!$X:$X, "<1") -> 0 | D15: =COUNTIFS('2025 NAP'!$D:$D, UPPER($B15), '2025 NAP'!$X:$X, ">=1", '2025 NAP'!$X:$X, "<=3") -> 1 | E15: =COUNTIFS('2025 NAP'!$D:$D, UPPER($B15), '2025 NAP'!$X:$X, ">3") -> 0 | F15: =COUNTIF('2025 NAP'!D:D,B15) -> 1
A16: Cluster 3 | B16: Aurora | C16: =COUNTIFS('2025 NAP'!$D:$D, UPPER($B16), '2025 NAP'!$X:$X, "<1") -> 0 | D16: =COUNTIFS('2025 NAP'!$D:$D, UPPER($B16), '2025 NAP'!$X:$X, ">=1", '2025 NAP'!$X:$X, "<=3") -> 0 | E16: =COUNTIFS('2025 NAP'!$D:$D, UPPER($B16), '2025 NAP'!$X:$X, ">3") -> 0 | F16: =COUNTIF('2025 NAP'!D:D,B16) -> 0
A17: Cluster 3 | B17: Quirino | C17: =COUNTIFS('2025 NAP'!$D:$D, UPPER($B17), '2025 NAP'!$X:$X, "<1") -> 0 | D17: =COUNTIFS('2025 NAP'!$D:$D, UPPER($B17), '2025 NAP'!$X:$X, ">=1", '2025 NAP'!$X:$X, "<=3") -> 0 | E17: =COUNTIFS('2025 NAP'!$D:$D, UPPER($B17), '2025 NAP'!$X:$X, ">3") -> 0 | F17: =COUNTIF('2025 NAP'!D:D,B17) -> 0
A18: Cluster 3 | B18: Kalinga | C18: =COUNTIFS('2025 NAP'!$D:$D, UPPER($B18), '2025 NAP'!$X:$X, "<1") -> 0 | D18: =COUNTIFS('2025 NAP'!$D:$D, UPPER($B18), '2025 NAP'!$X:$X, ">=1", '2025 NAP'!$X:$X, "<=3") -> 0 | E18: =COUNTIFS('2025 NAP'!$D:$D, UPPER($B18), '2025 NAP'!$X:$X, ">3") -> 0 | F18: =COUNTIF('2025 NAP'!D:D,B18) -> 0
B19: TOTAL | C19: =SUM(C3:C18) -> 32 | D19: =SUM(D3:D18) -> 24 | E19: =SUM(E3:E18) -> 15 | F19: =SUM(F3:F18) -> 71

Sheet NLZ LCP Report
A1: LCP REPORT | G1: LCP REPORT
A2: AREA | B2: PROVINCE | C2: TT COUNT | D2: LCP COUNT | E2: CLIENTS | G2: AREA | H2: PROVINCE | I2: TT COUNT | J2: LCP COUNT | K2: CLIENTS
A3: Cluster 2 | B3: Abra | C3: =COUNTIF('LCP Tickets'!D:D,B3) -> 0 | D3: =SUMIF('LCP Tickets'!$D:$D, B3, 'LCP Tickets'!$AB:$AB) -> 0 | E3: =SUMIF('LCP Tickets'!$D:$D, B3, 'LCP Tickets'!$AC:$AC) -> 0 | G3: =IFERROR(__xludf.DUMMYFUNCTION("{ SORT(FILTER(A3:E18, E3:E18 > 0), 5, FALSE); {""TOTAL"", """", SUM(C3:C18), SUM(D3:D18), SUM(E3:E18)} }"),"Cluster 1") -> Cluster 1 | H3: =IFERROR(__xludf.DUMMYFUNCTION("""COMPUTED_VALUE"""),"Pangasinan") -> Pangasinan | I3: =IFERROR(__xludf.DUMMYFUNCTION("""COMPUTED_VALUE"""),2.0) -> 2 | J3: =IFERROR(__xludf.DUMMYFUNCTION("""COMPUTED_VALUE"""),12.0) -> 12 | K3: =IFERROR(__xludf.DUMMYFUNCTION("""COMPUTED_VALUE"""),498.0) -> 498
A4: Cluster 3 | B4: Apayao | C4: =COUNTIF('LCP Tickets'!D:D,B4) -> 0 | D4: =SUMIF('LCP Tickets'!$D:$D, B4, 'LCP Tickets'!$AB:$AB) -> 0 | E4: =SUMIF('LCP Tickets'!$D:$D, B4, 'LCP Tickets'!$AC:$AC) -> 0 | G4: =IFERROR(__xludf.DUMMYFUNCTION("""COMPUTED_VALUE"""),"Cluster 3") -> Cluster 3 | H4: =IFERROR(__xludf.DUMMYFUNCTION("""COMPUTED_VALUE"""),"Nueva_Vizcaya") -> Nueva_Vizcaya | I4: =IFERROR(__xludf.DUMMYFUNCTION("""COMPUTED_VALUE"""),1.0) -> 1 | J4: =IFERROR(__xludf.DUMMYFUNCTION("""COMPUTED_VALUE"""),12.0) -> 12 | K4: =IFERROR(__xludf.DUMMYFUNCTION("""COMPUTED_VALUE"""),245.0) -> 245
A5: Cluster 3 | B5: Aurora | C5: =COUNTIF('LCP Tickets'!D:D,B5) -> 0 | D5: =SUMIF('LCP Tickets'!$D:$D, B5, 'LCP Tickets'!$AB:$AB) -> 0 | E5: =SUMIF('LCP Tickets'!$D:$D, B5, 'LCP Tickets'!$AC:$AC) -> 0 | G5: =IFERROR(__xludf.DUMMYFUNCTION("""COMPUTED_VALUE"""),"Cluster 2") -> Cluster 2 | H5: =IFERROR(__xludf.DUMMYFUNCTION("""COMPUTED_VALUE"""),"Ilocos_Norte") -> Ilocos_Norte | I5: =IFERROR(__xludf.DUMMYFUNCTION("""COMPUTED_VALUE"""),3.0) -> 3 | J5: =IFERROR(__xludf.DUMMYFUNCTION("""COMPUTED_VALUE"""),5.0) -> 5 | K5: =IFERROR(__xludf.DUMMYFUNCTION("""COMPUTED_VALUE"""),88.0) -> 88
A6: Cluster 2 | B6: Benguet | C6: =COUNTIF('LCP Tickets'!D:D,B6) -> 4 | D6: =SUMIF('LCP Tickets'!$D:$D, B6, 'LCP Tickets'!$AB:$AB) -> 5 | E6: =SUMIF('LCP Tickets'!$D:$D, B6, 'LCP Tickets'!$AC:$AC) -> 21 | G6: =IFERROR(__xludf.DUMMYFUNCTION("""COMPUTED_VALUE"""),"Cluster 2") -> Cluster 2 | H6: =IFERROR(__xludf.DUMMYFUNCTION("""COMPUTED_VALUE"""),"Benguet") -> Benguet | I6: =IFERROR(__xludf.DUMMYFUNCTION("""COMPUTED_VALUE"""),4.0) -> 4 | J6: =IFERROR(__xludf.DUMMYFUNCTION("""COMPUTED_VALUE"""),5.0) -> 5 | K6: =IFERROR(__xludf.DUMMYFUNCTION("""COMPUTED_VALUE"""),21.0) -> 21
A7: Cluster 3 | B7: Cagayan | C7: =COUNTIF('LCP Tickets'!D:D,B7) -> 0 | D7: =SUMIF('LCP Tickets'!$D:$D, B7, 'LCP Tickets'!$AB:$AB) -> 0 | E7: =SUMIF('LCP Tickets'!$D:$D, B7, 'LCP Tickets'!$AC:$AC) -> 0 | G7: =IFERROR(__xludf.DUMMYFUNCTION("""COMPUTED_VALUE"""),"Cluster 3") -> Cluster 3 | H7: =IFERROR(__xludf.DUMMYFUNCTION("""COMPUTED_VALUE"""),"Ifugao") -> Ifugao | I7: =IFERROR(__xludf.DUMMYFUNCTION("""COMPUTED_VALUE"""),1.0) -> 1 | J7: =IFERROR(__xludf.DUMMYFUNCTION("""COMPUTED_VALUE"""),1.0) -> 1 | K7: =IFERROR(__xludf.DUMMYFUNCTION("""COMPUTED_VALUE"""),7.0) -> 7
A8: Cluster 3 | B8: Ifugao | C8: =COUNTIF('LCP Tickets'!D:D,B8) -> 1 | D8: =SUMIF('LCP Tickets'!$D:$D, B8, 'LCP Tickets'!$AB:$AB) -> 1 | E8: =SUMIF('LCP Tickets'!$D:$D, B8, 'LCP Tickets'!$AC:$AC) -> 7 | G8: =IFERROR(__xludf.DUMMYFUNCTION("""COMPUTED_VALUE"""),"TOTAL") -> TOTAL | H8: =IFERROR(__xludf.DUMMYFUNCTION("""COMPUTED_VALUE"""),"") | I8: =IFERROR(__xludf.DUMMYFUNCTION("""COMPUTED_VALUE"""),11.0) -> 11 | J8: =IFERROR(__xludf.DUMMYFUNCTION("""COMPUTED_VALUE"""),35.0) -> 35 | K8: =IFERROR(__xludf.DUMMYFUNCTION("""COMPUTED_VALUE"""),859.0) -> 859
A9: Cluster 2 | B9: Ilocos_Norte | C9: =COUNTIF('LCP Tickets'!D:D,B9) -> 3 | D9: =SUMIF('LCP Tickets'!$D:$D, B9, 'LCP Tickets'!$AB:$AB) -> 5 | E9: =SUMIF('LCP Tickets'!$D:$D, B9, 'LCP Tickets'!$AC:$AC) -> 88
A10: Cluster 2 | B10: Ilocos_Sur | C10: =COUNTIF('LCP Tickets'!D:D,B10) -> 0 | D10: =SUMIF('LCP Tickets'!$D:$D, B10, 'LCP Tickets'!$AB:$AB) -> 0 | E10: =SUMIF('LCP Tickets'!$D:$D, B10, 'LCP Tickets'!$AC:$AC) -> 0
A11: Cluster 3 | B11: Isabela | C11: =COUNTIF('LCP Tickets'!D:D,B11) -> 0 | D11: =SUMIF('LCP Tickets'!$D:$D, B11, 'LCP Tickets'!$AB:$AB) -> 0 | E11: =SUMIF('LCP Tickets'!$D:$D, B11, 'LCP Tickets'!$AC:$AC) -> 0
A12: Cluster 3 | B12: Kalinga | C12: =COUNTIF('LCP Tickets'!D:D,B12) -> 0 | D12: =SUMIF('LCP Tickets'!$D:$D, B12, 'LCP Tickets'!$AB:$AB) -> 0 | E12: =SUMIF('LCP Tickets'!$D:$D, B12, 'LCP Tickets'!$AC:$AC) -> 0
A13: Cluster 2 | B13: La_Union | C13: =COUNTIF('LCP Tickets'!D:D,B13) -> 0 | D13: =SUMIF('LCP Tickets'!$D:$D, B13, 'LCP Tickets'!$AB:$AB) -> 0 | E13: =SUMIF('LCP Tickets'!$D:$D, B13, 'LCP Tickets'!$AC:$AC) -> 0
A14: Cluster 2 | B14: Mt_Province | C14: =COUNTIF('LCP Tickets'!D:D,B14) -> 0 | D14: =SUMIF('LCP Tickets'!$D:$D, B14, 'LCP Tickets'!$AB:$AB) -> 0 | E14: =SUMIF('LCP Tickets'!$D:$D, B14, 'LCP Tickets'!$AC:$AC) -> 0
A15: Cluster 3 | B15: Nueva_Ecija | C15: =COUNTIF('LCP Tickets'!D:D,B15) -> 0 | D15: =SUMIF('LCP Tickets'!$D:$D, B15, 'LCP Tickets'!$AB:$AB) -> 0 | E15: =SUMIF('LCP Tickets'!$D:$D, B15, 'LCP Tickets'!$AC:$AC) -> 0
A16: Cluster 3 | B16: Nueva_Vizcaya | C16: =COUNTIF('LCP Tickets'!D:D,B16) -> 1 | D16: =SUMIF('LCP Tickets'!$D:$D, B16, 'LCP Tickets'!$AB:$AB) -> 12 | E16: =SUMIF('LCP Tickets'!$D:$D, B16, 'LCP Tickets'!$AC:$AC) -> 245
A17: Cluster 1 | B17: Pangasinan | C17: =COUNTIF('LCP Tickets'!D:D,B17) -> 2 | D17: =SUMIF('LCP Tickets'!$D:$D, B17, 'LCP Tickets'!$AB:$AB) -> 12 | E17: =SUMIF('LCP Tickets'!$D:$D, B17, 'LCP Tickets'!$AC:$AC) -> 498
A18: Cluster 3 | B18: Quirino | C18: =COUNTIF('LCP Tickets'!D:D,B18) -> 0 | D18: =SUMIF('LCP Tickets'!$D:$D, B18, 'LCP Tickets'!$AB:$AB) -> 0 | E18: =SUMIF('LCP Tickets'!$D:$D, B18, 'LCP Tickets'!$AC:$AC) -> 0
B19: TOTAL | C19: =SUM(C3:C18) -> 11 | D19: =SUM(D3:D18) -> 35 | E19: =SUM(E3:E18) -> 859
A22: LCP Aging Report | G22: LCP AGING REPORT
A23: AREA | B23: PROVINCE | C23: <24HOURS | D23: 1-3 DAYS | E23: >3DAYS | F23: TOTAL | G23: AREA | H23: PROVINCE | I23: <24HOURS | J23: 1-3 DAYS | K23: >3DAYS | L23: TOTAL
A24: Cluster 2 | B24: Abra | C24: =SUMIFS('LCP Tickets'!$AB:$AB, 'LCP Tickets'!$D:$D, UPPER($B24), 'LCP Tickets'!$AA:$AA, "<1") -> 0 | D24: =SUMIFS('LCP Tickets'!$AB:$AB, 'LCP Tickets'!$D:$D, UPPER($B24), 'LCP Tickets'!$AA:$AA, ">=1", 'LCP Tickets'!$AA:$AA, "<=3") -> 0 | E24: =SUMIFS('LCP Tickets'!$AB:$AB, 'LCP Tickets'!$D:$D, UPPER($B24), 'LCP Tickets'!$AA:$AA, ">3") -> 0 | F24: =SUM(C24:E24) -> 0 | G24: =IFERROR(__xludf.DUMMYFUNCTION("{ SORT(FILTER(A24:F39, F24:F39 > 0), 6, FALSE); {""TOTAL"", """", SUM(C24:C39), SUM(D24:D39), SUM(E24:E39), SUM(F24:F39)} }"),"Cluster 3") -> Cluster 3 | H24: =IFERROR(__xludf.DUMMYFUNCTION("""COMPUTED_VALUE"""),"Nueva_Vizcaya") -> Nueva_Vizcaya | I24: =IFERROR(__xludf.DUMMYFUNCTION("""COMPUTED_VALUE"""),12.0) -> 12 | J24: =IFERROR(__xludf.DUMMYFUNCTION("""COMPUTED_VALUE"""),0.0) -> 0 | K24: =IFERROR(__xludf.DUMMYFUNCTION("""COMPUTED_VALUE"""),0.0) -> 0 | L24: =IFERROR(__xludf.DUMMYFUNCTION("""COMPUTED_VALUE"""),12.0) -> 12
A25: Cluster 3 | B25: Apayao | C25: =SUMIFS('LCP Tickets'!$AB:$AB, 'LCP Tickets'!$D:$D, UPPER($B25), 'LCP Tickets'!$AA:$AA, "<1") -> 0 | D25: =SUMIFS('LCP Tickets'!$AB:$AB, 'LCP Tickets'!$D:$D, UPPER($B25), 'LCP Tickets'!$AA:$AA, ">=1", 'LCP Tickets'!$AA:$AA, "<=3") -> 0 | E25: =SUMIFS('LCP Tickets'!$AB:$AB, 'LCP Tickets'!$D:$D, UPPER($B25), 'LCP Tickets'!$AA:$AA, ">3") -> 0 | F25: =SUM(C25:E25) -> 0 | G25: =IFERROR(__xludf.DUMMYFUNCTION("""COMPUTED_VALUE"""),"Cluster 1") -> Cluster 1 | H25: =IFERROR(__xludf.DUMMYFUNCTION("""COMPUTED_VALUE"""),"Pangasinan") -> Pangasinan | I25: =IFERROR(__xludf.DUMMYFUNCTION("""COMPUTED_VALUE"""),12.0) -> 12 | J25: =IFERROR(__xludf.DUMMYFUNCTION("""COMPUTED_VALUE"""),0.0) -> 0 | K25: =IFERROR(__xludf.DUMMYFUNCTION("""COMPUTED_VALUE"""),0.0) -> 0 | L25: =IFERROR(__xludf.DUMMYFUNCTION("""COMPUTED_VALUE"""),12.0) -> 12
A26: Cluster 3 | B26: Aurora | C26: =SUMIFS('LCP Tickets'!$AB:$AB, 'LCP Tickets'!$D:$D, UPPER($B26), 'LCP Tickets'!$AA:$AA, "<1") -> 0 | D26: =SUMIFS('LCP Tickets'!$AB:$AB, 'LCP Tickets'!$D:$D, UPPER($B26), 'LCP Tickets'!$AA:$AA, ">=1", 'LCP Tickets'!$AA:$AA, "<=3") -> 0 | E26: =SUMIFS('LCP Tickets'!$AB:$AB, 'LCP Tickets'!$D:$D, UPPER($B26), 'LCP Tickets'!$AA:$AA, ">3") -> 0 | F26: =SUM(C26:E26) -> 0 | G26: =IFERROR(__xludf.DUMMYFUNCTION("""COMPUTED_VALUE"""),"Cluster 2") -> Cluster 2 | H26: =IFERROR(__xludf.DUMMYFUNCTION("""COMPUTED_VALUE"""),"Benguet") -> Benguet | I26: =IFERROR(__xludf.DUMMYFUNCTION("""COMPUTED_VALUE"""),1.0) -> 1 | J26: =IFERROR(__xludf.DUMMYFUNCTION("""COMPUTED_VALUE"""),1.0) -> 1 | K26: =IFERROR(__xludf.DUMMYFUNCTION("""COMPUTED_VALUE"""),3.0) -> 3 | L26: =IFERROR(__xludf.DUMMYFUNCTION("""COMPUTED_VALUE"""),5.0) -> 5
A27: Cluster 2 | B27: Benguet | C27: =SUMIFS('LCP Tickets'!$AB:$AB, 'LCP Tickets'!$D:$D, UPPER($B27), 'LCP Tickets'!$AA:$AA, "<1") -> 1 | D27: =SUMIFS('LCP Tickets'!$AB:$AB, 'LCP Tickets'!$D:$D, UPPER($B27), 'LCP Tickets'!$AA:$AA, ">=1", 'LCP Tickets'!$AA:$AA, "<=3") -> 1 | E27: =SUMIFS('LCP Tickets'!$AB:$AB, 'LCP Tickets'!$D:$D, UPPER($B27), 'LCP Tickets'!$AA:$AA, ">3") -> 3 | F27: =SUM(C27:E27) -> 5 | G27: =IFERROR(__xludf.DUMMYFUNCTION("""COMPUTED_VALUE"""),"Cluster 2") -> Cluster 2 | H27: =IFERROR(__xludf.DUMMYFUNCTION("""COMPUTED_VALUE"""),"Ilocos_Norte") -> Ilocos_Norte | I27: =IFERROR(__xludf.DUMMYFUNCTION("""COMPUTED_VALUE"""),5.0) -> 5 | J27: =IFERROR(__xludf.DUMMYFUNCTION("""COMPUTED_VALUE"""),0.0) -> 0 | K27: =IFERROR(__xludf.DUMMYFUNCTION("""COMPUTED_VALUE"""),0.0) -> 0 | L27: =IFERROR(__xludf.DUMMYFUNCTION("""COMPUTED_VALUE"""),5.0) -> 5
A28: Cluster 3 | B28: Cagayan | C28: =SUMIFS('LCP Tickets'!$AB:$AB, 'LCP Tickets'!$D:$D, UPPER($B28), 'LCP Tickets'!$AA:$AA, "<1") -> 0 | D28: =SUMIFS('LCP Tickets'!$AB:$AB, 'LCP Tickets'!$D:$D, UPPER($B28), 'LCP Tickets'!$AA:$AA, ">=1", 'LCP Tickets'!$AA:$AA, "<=3") -> 0 | E28: =SUMIFS('LCP Tickets'!$AB:$AB, 'LCP Tickets'!$D:$D, UPPER($B28), 'LCP Tickets'!$AA:$AA, ">3") -> 0 | F28: =SUM(C28:E28) -> 0 | G28: =IFERROR(__xludf.DUMMYFUNCTION("""COMPUTED_VALUE"""),"Cluster 3") -> Cluster 3 | H28: =IFERROR(__xludf.DUMMYFUNCTION("""COMPUTED_VALUE"""),"Ifugao") -> Ifugao | I28: =IFERROR(__xludf.DUMMYFUNCTION("""COMPUTED_VALUE"""),0.0) -> 0 | J28: =IFERROR(__xludf.DUMMYFUNCTION("""COMPUTED_VALUE"""),1.0) -> 1 | K28: =IFERROR(__xludf.DUMMYFUNCTION("""COMPUTED_VALUE"""),0.0) -> 0 | L28: =IFERROR(__xludf.DUMMYFUNCTION("""COMPUTED_VALUE"""),1.0) -> 1
A29: Cluster 3 | B29: Ifugao | C29: =SUMIFS('LCP Tickets'!$AB:$AB, 'LCP Tickets'!$D:$D, UPPER($B29), 'LCP Tickets'!$AA:$AA, "<1") -> 0 | D29: =SUMIFS('LCP Tickets'!$AB:$AB, 'LCP Tickets'!$D:$D, UPPER($B29), 'LCP Tickets'!$AA:$AA, ">=1", 'LCP Tickets'!$AA:$AA, "<=3") -> 1 | E29: =SUMIFS('LCP Tickets'!$AB:$AB, 'LCP Tickets'!$D:$D, UPPER($B29), 'LCP Tickets'!$AA:$AA, ">3") -> 0 | F29: =SUM(C29:E29) -> 1 | G29: =IFERROR(__xludf.DUMMYFUNCTION("""COMPUTED_VALUE"""),"TOTAL") -> TOTAL | H29: =IFERROR(__xludf.DUMMYFUNCTION("""COMPUTED_VALUE"""),"") | I29: =IFERROR(__xludf.DUMMYFUNCTION("""COMPUTED_VALUE"""),30.0) -> 30 | J29: =IFERROR(__xludf.DUMMYFUNCTION("""COMPUTED_VALUE"""),2.0) -> 2 | K29: =IFERROR(__xludf.DUMMYFUNCTION("""COMPUTED_VALUE"""),3.0) -> 3 | L29: =IFERROR(__xludf.DUMMYFUNCTION("""COMPUTED_VALUE"""),35.0) -> 35
A30: Cluster 2 | B30: Ilocos_Norte | C30: =SUMIFS('LCP Tickets'!$AB:$AB, 'LCP Tickets'!$D:$D, UPPER($B30), 'LCP Tickets'!$AA:$AA, "<1") -> 5 | D30: =SUMIFS('LCP Tickets'!$AB:$AB, 'LCP Tickets'!$D:$D, UPPER($B30), 'LCP Tickets'!$AA:$AA, ">=1", 'LCP Tickets'!$AA:$AA, "<=3") -> 0 | E30: =SUMIFS('LCP Tickets'!$AB:$AB, 'LCP Tickets'!$D:$D, UPPER($B30), 'LCP Tickets'!$AA:$AA, ">3") -> 0 | F30: =SUM(C30:E30) -> 5
A31: Cluster 2 | B31: Ilocos_Sur | C31: =SUMIFS('LCP Tickets'!$AB:$AB, 'LCP Tickets'!$D:$D, UPPER($B31), 'LCP Tickets'!$AA:$AA, "<1") -> 0 | D31: =SUMIFS('LCP Tickets'!$AB:$AB, 'LCP Tickets'!$D:$D, UPPER($B31), 'LCP Tickets'!$AA:$AA, ">=1", 'LCP Tickets'!$AA:$AA, "<=3") -> 0 | E31: =SUMIFS('LCP Tickets'!$AB:$AB, 'LCP Tickets'!$D:$D, UPPER($B31), 'LCP Tickets'!$AA:$AA, ">3") -> 0 | F31: =SUM(C31:E31) -> 0
A32: Cluster 3 | B32: Isabela | C32: =SUMIFS('LCP Tickets'!$AB:$AB, 'LCP Tickets'!$D:$D, UPPER($B32), 'LCP Tickets'!$AA:$AA, "<1") -> 0 | D32: =SUMIFS('LCP Tickets'!$AB:$AB, 'LCP Tickets'!$D:$D, UPPER($B32), 'LCP Tickets'!$AA:$AA, ">=1", 'LCP Tickets'!$AA:$AA, "<=3") -> 0 | E32: =SUMIFS('LCP Tickets'!$AB:$AB, 'LCP Tickets'!$D:$D, UPPER($B32), 'LCP Tickets'!$AA:$AA, ">3") -> 0 | F32: =SUM(C32:E32) -> 0
A33: Cluster 3 | B33: Kalinga | C33: =SUMIFS('LCP Tickets'!$AB:$AB, 'LCP Tickets'!$D:$D, UPPER($B33), 'LCP Tickets'!$AA:$AA, "<1") -> 0 | D33: =SUMIFS('LCP Tickets'!$AB:$AB, 'LCP Tickets'!$D:$D, UPPER($B33), 'LCP Tickets'!$AA:$AA, ">=1", 'LCP Tickets'!$AA:$AA, "<=3") -> 0 | E33: =SUMIFS('LCP Tickets'!$AB:$AB, 'LCP Tickets'!$D:$D, UPPER($B33), 'LCP Tickets'!$AA:$AA, ">3") -> 0 | F33: =SUM(C33:E33) -> 0
A34: Cluster 2 | B34: La_Union | C34: =SUMIFS('LCP Tickets'!$AB:$AB, 'LCP Tickets'!$D:$D, UPPER($B34), 'LCP Tickets'!$AA:$AA, "<1") -> 0 | D34: =SUMIFS('LCP Tickets'!$AB:$AB, 'LCP Tickets'!$D:$D, UPPER($B34), 'LCP Tickets'!$AA:$AA, ">=1", 'LCP Tickets'!$AA:$AA, "<=3") -> 0 | E34: =SUMIFS('LCP Tickets'!$AB:$AB, 'LCP Tickets'!$D:$D, UPPER($B34), 'LCP Tickets'!$AA:$AA, ">3") -> 0 | F34: =SUM(C34:E34) -> 0
A35: Cluster 2 | B35: Mt_Province | C35: =SUMIFS('LCP Tickets'!$AB:$AB, 'LCP Tickets'!$D:$D, UPPER($B35), 'LCP Tickets'!$AA:$AA, "<1") -> 0 | D35: =SUMIFS('LCP Tickets'!$AB:$AB, 'LCP Tickets'!$D:$D, UPPER($B35), 'LCP Tickets'!$AA:$AA, ">=1", 'LCP Tickets'!$AA:$AA, "<=3") -> 0 | E35: =SUMIFS('LCP Tickets'!$AB:$AB, 'LCP Tickets'!$D:$D, UPPER($B35), 'LCP Tickets'!$AA:$AA, ">3") -> 0 | F35: =SUM(C35:E35) -> 0
A36: Cluster 3 | B36: Nueva_Ecija | C36: =SUMIFS('LCP Tickets'!$AB:$AB, 'LCP Tickets'!$D:$D, UPPER($B36), 'LCP Tickets'!$AA:$AA, "<1") -> 0 | D36: =SUMIFS('LCP Tickets'!$AB:$AB, 'LCP Tickets'!$D:$D, UPPER($B36), 'LCP Tickets'!$AA:$AA, ">=1", 'LCP Tickets'!$AA:$AA, "<=3") -> 0 | E36: =SUMIFS('LCP Tickets'!$AB:$AB, 'LCP Tickets'!$D:$D, UPPER($B36), 'LCP Tickets'!$AA:$AA, ">3") -> 0 | F36: =SUM(C36:E36) -> 0
A37: Cluster 3 | B37: Nueva_Vizcaya | C37: =SUMIFS('LCP Tickets'!$AB:$AB, 'LCP Tickets'!$D:$D, UPPER($B37), 'LCP Tickets'!$AA:$AA, "<1") -> 12 | D37: =SUMIFS('LCP Tickets'!$AB:$AB, 'LCP Tickets'!$D:$D, UPPER($B37), 'LCP Tickets'!$AA:$AA, ">=1", 'LCP Tickets'!$AA:$AA, "<=3") -> 0 | E37: =SUMIFS('LCP Tickets'!$AB:$AB, 'LCP Tickets'!$D:$D, UPPER($B37), 'LCP Tickets'!$AA:$AA, ">3") -> 0 | F37: =SUM(C37:E37) -> 12
A38: Cluster 1 | B38: Pangasinan | C38: =SUMIFS('LCP Tickets'!$AB:$AB, 'LCP Tickets'!$D:$D, UPPER($B38), 'LCP Tickets'!$AA:$AA, "<1") -> 12 | D38: =SUMIFS('LCP Tickets'!$AB:$AB, 'LCP Tickets'!$D:$D, UPPER($B38), 'LCP Tickets'!$AA:$AA, ">=1", 'LCP Tickets'!$AA:$AA, "<=3") -> 0 | E38: =SUMIFS('LCP Tickets'!$AB:$AB, 'LCP Tickets'!$D:$D, UPPER($B38), 'LCP Tickets'!$AA:$AA, ">3") -> 0 | F38: =SUM(C38:E38) -> 12
A39: Cluster 3 | B39: Quirino | C39: =SUMIFS('LCP Tickets'!$AB:$AB, 'LCP Tickets'!$D:$D, UPPER($B39), 'LCP Tickets'!$AA:$AA, "<1") -> 0 | D39: =SUMIFS('LCP Tickets'!$AB:$AB, 'LCP Tickets'!$D:$D, UPPER($B39), 'LCP Tickets'!$AA:$AA, ">=1", 'LCP Tickets'!$AA:$AA, "<=3") -> 0 | E39: =SUMIFS('LCP Tickets'!$AB:$AB, 'LCP Tickets'!$D:$D, UPPER($B39), 'LCP Tickets'!$AA:$AA, ">3") -> 0 | F39: =SUM(C39:E39) -> 0
B40: TOTAL | C40: =SUM(C24:C39) -> 30 | D40: =SUM(D24:D39) -> 2 | E40: =SUM(E24:E39) -> 3 | F40: =SUM(F24:F39) -> 35

Sheet NLZ OLT Report
E1: OLT STATUS | J1: TICKET NUMBER AND AGE | N1: CAUSE OF OUTAGE
A2: CLUSTER | B2: PROVINCE | C2: MUNICIPALITY | D2: OLT NAME | E2: UP | F2: DOWN | G2: OLT UPLINK LOW POWER | H2: OLT UPLINK DOWN | I2: OLT SERVICE DEGRADATION | J2: DOWN | K2: OLT UPLINK LOW POWER | L2: OLT UPLINK DOWN | M2: OLT SERVICE DEGRADATION | N2: FIBER | O2: POWER | P2: EQUIPMENT | Q2: TBD
B3: ABRA | C3: BANGUED | D3: BDA001-OLT-01 | E3: =NOT(OR(F3, G3, H3, I3)) -> TRUE | F3: =COUNTIFS('OLT DOWN Tickets'!$AB:$AB, "*" & D3 & "*", 'OLT DOWN Tickets'!$L:$L, "OLT DOWN") > 0 -> FALSE | G3: =COUNTIFS('OLT DOWN Tickets'!$AB:$AB, "*" & D3 & "*", 'OLT DOWN Tickets'!$L:$L, "OLT UPLINK LOW POWER") > 0 -> FALSE | H3: =COUNTIFS('OLT DOWN Tickets'!$AB:$AB, "*" & D3 & "*", 'OLT DOWN Tickets'!$L:$L, "OLT UPLINK DOWN") > 0 -> FALSE | I3: =COUNTIFS('OLT DOWN Tickets'!$AB:$AB, "*" & D3 & "*", 'OLT DOWN Tickets'!$L:$L, "OLT SERVICE DEGRADATION") > 0 -> FALSE | J3: =IFERROR(__xludf.DUMMYFUNCTION("IFERROR(INDEX(FILTER('OLT DOWN Tickets'!$F:$F, REGEXMATCH('OLT DOWN Tickets'!$AB:$AB, ""(?i)""&TRIM(D3)), 'OLT DOWN Tickets'!$L:$L=""OLT DOWN""), 1), """")"),"") | K3: =IFERROR(__xludf.DUMMYFUNCTION("IFERROR(INDEX(FILTER('OLT DOWN Tickets'!$F:$F, REGEXMATCH('OLT DOWN Tickets'!$AB:$AB, ""(?i)""&TRIM(D3)), 'OLT DOWN Tickets'!$L:$L=""OLT UPLINK LOW POWER""), 1), """")"),"") | L3: =IFERROR(__xludf.DUMMYFUNCTION("IFERROR(INDEX(FILTER('OLT DOWN Tickets'!$F:$F, REGEXMATCH('OLT DOWN Tickets'!$AB:$AB, ""(?i)""&TRIM(D3)), 'OLT DOWN Tickets'!$L:$L=""OLT UPLINK DOWN""), 1), """")"),"") | M3: =IFERROR(__xludf.DUMMYFUNCTION("IFERROR(INDEX(FILTER('OLT DOWN Tickets'!$F:$F, REGEXMATCH('OLT DOWN Tickets'!$AB:$AB, ""(?i)""&TRIM(D3)), 'OLT DOWN Tickets'!$L:$L=""OLT SERVICE DEGRADATION""), 1), """") "),"") | N3: FALSE | O3: FALSE | P3: FALSE | Q3: FALSE
B4: ABRA | C4: LAPAZ | D4: LPA001-OLT-01 | E4: =NOT(OR(F4, G4, H4, I4)) -> TRUE | F4: =COUNTIFS('OLT DOWN Tickets'!$AB:$AB, "*" & D4 & "*", 'OLT DOWN Tickets'!$L:$L, "OLT DOWN") > 0 -> FALSE | G4: =COUNTIFS('OLT DOWN Tickets'!$AB:$AB, "*" & D4 & "*", 'OLT DOWN Tickets'!$L:$L, "OLT UPLINK LOW POWER") > 0 -> FALSE | H4: =COUNTIFS('OLT DOWN Tickets'!$AB:$AB, "*" & D4 & "*", 'OLT DOWN Tickets'!$L:$L, "OLT UPLINK DOWN") > 0 -> FALSE | I4: =COUNTIFS('OLT DOWN Tickets'!$AB:$AB, "*" & D4 & "*", 'OLT DOWN Tickets'!$L:$L, "OLT SERVICE DEGRADATION") > 0 -> FALSE | J4: =IFERROR(__xludf.DUMMYFUNCTION("IFERROR(INDEX(FILTER('OLT DOWN Tickets'!$F:$F, REGEXMATCH('OLT DOWN Tickets'!$AB:$AB, ""(?i)""&TRIM(D4)), 'OLT DOWN Tickets'!$L:$L=""OLT DOWN""), 1), """")"),"") | K4: =IFERROR(__xludf.DUMMYFUNCTION("IFERROR(INDEX(FILTER('OLT DOWN Tickets'!$F:$F, REGEXMATCH('OLT DOWN Tickets'!$AB:$AB, ""(?i)""&TRIM(D4)), 'OLT DOWN Tickets'!$L:$L=""OLT UPLINK LOW POWER""), 1), """")"),"") | L4: =IFERROR(__xludf.DUMMYFUNCTION("IFERROR(INDEX(FILTER('OLT DOWN Tickets'!$F:$F, REGEXMATCH('OLT DOWN Tickets'!$AB:$AB, ""(?i)""&TRIM(D4)), 'OLT DOWN Tickets'!$L:$L=""OLT UPLINK DOWN""), 1), """")"),"") | M4: =IFERROR(__xludf.DUMMYFUNCTION("IFERROR(INDEX(FILTER('OLT DOWN Tickets'!$F:$F, REGEXMATCH('OLT DOWN Tickets'!$AB:$AB, ""(?i)""&TRIM(D4)), 'OLT DOWN Tickets'!$L:$L=""OLT SERVICE DEGRADATION""), 1), """") "),"") | N4: FALSE | O4: FALSE | P4: FALSE | Q4: FALSE
B5: ABRA | C5: PIDIGAN | D5: PNA001-OLT-01 | E5: =NOT(OR(F5, G5, H5, I5)) -> TRUE | F5: =COUNTIFS('OLT DOWN Tickets'!$AB:$AB, "*" & D5 & "*", 'OLT DOWN Tickets'!$L:$L, "OLT DOWN") > 0 -> FALSE | G5: =COUNTIFS('OLT DOWN Tickets'!$AB:$AB, "*" & D5 & "*", 'OLT DOWN Tickets'!$L:$L, "OLT UPLINK LOW POWER") > 0 -> FALSE | H5: =COUNTIFS('OLT DOWN Tickets'!$AB:$AB, "*" & D5 & "*", 'OLT DOWN Tickets'!$L:$L, "OLT UPLINK DOWN") > 0 -> FALSE | I5: =COUNTIFS('OLT DOWN Tickets'!$AB:$AB, "*" & D5 & "*", 'OLT DOWN Tickets'!$L:$L, "OLT SERVICE DEGRADATION") > 0 -> FALSE | J5: =IFERROR(__xludf.DUMMYFUNCTION("IFERROR(INDEX(FILTER('OLT DOWN Tickets'!$F:$F, REGEXMATCH('OLT DOWN Tickets'!$AB:$AB, ""(?i)""&TRIM(D5)), 'OLT DOWN Tickets'!$L:$L=""OLT DOWN""), 1), """")"),"") | K5: =IFERROR(__xludf.DUMMYFUNCTION("IFERROR(INDEX(FILTER('OLT DOWN Tickets'!$F:$F, REGEXMATCH('OLT DOWN Tickets'!$AB:$AB, ""(?i)""&TRIM(D5)), 'OLT DOWN Tickets'!$L:$L=""OLT UPLINK LOW POWER""), 1), """")"),"") | L5: =IFERROR(__xludf.DUMMYFUNCTION("IFERROR(INDEX(FILTER('OLT DOWN Tickets'!$F:$F, REGEXMATCH('OLT DOWN Tickets'!$AB:$AB, ""(?i)""&TRIM(D5)), 'OLT DOWN Tickets'!$L:$L=""OLT UPLINK DOWN""), 1), """")"),"") | M5: =IFERROR(__xludf.DUMMYFUNCTION("IFERROR(INDEX(FILTER('OLT DOWN Tickets'!$F:$F, REGEXMATCH('OLT DOWN Tickets'!$AB:$AB, ""(?i)""&TRIM(D5)), 'OLT DOWN Tickets'!$L:$L=""OLT SERVICE DEGRADATION""), 1), """") "),"") | N5: FALSE | O5: FALSE | P5: FALSE | Q5: FALSE
B6: APAYAO | C6: CONNER | D6: CRY001-OLT-01 | E6: =NOT(OR(F6, G6, H6, I6)) -> TRUE | F6: =COUNTIFS('OLT DOWN Tickets'!$AB:$AB, "*" & D6 & "*", 'OLT DOWN Tickets'!$L:$L, "OLT DOWN") > 0 -> FALSE | G6: =COUNTIFS('OLT DOWN Tickets'!$AB:$AB, "*" & D6 & "*", 'OLT DOWN Tickets'!$L:$L, "OLT UPLINK LOW POWER") > 0 -> FALSE | H6: =COUNTIFS('OLT DOWN Tickets'!$AB:$AB, "*" & D6 & "*", 'OLT DOWN Tickets'!$L:$L, "OLT UPLINK DOWN") > 0 -> FALSE | I6: =COUNTIFS('OLT DOWN Tickets'!$AB:$AB, "*" & D6 & "*", 'OLT DOWN Tickets'!$L:$L, "OLT SERVICE DEGRADATION") > 0 -> FALSE | J6: =IFERROR(__xludf.DUMMYFUNCTION("IFERROR(INDEX(FILTER('OLT DOWN Tickets'!$F:$F, REGEXMATCH('OLT DOWN Tickets'!$AB:$AB, ""(?i)""&TRIM(D6)), 'OLT DOWN Tickets'!$L:$L=""OLT DOWN""), 1), """")"),"") | K6: =IFERROR(__xludf.DUMMYFUNCTION("IFERROR(INDEX(FILTER('OLT DOWN Tickets'!$F:$F, REGEXMATCH('OLT DOWN Tickets'!$AB:$AB, ""(?i)""&TRIM(D6)), 'OLT DOWN Tickets'!$L:$L=""OLT UPLINK LOW POWER""), 1), """")"),"") | L6: =IFERROR(__xludf.DUMMYFUNCTION("IFERROR(INDEX(FILTER('OLT DOWN Tickets'!$F:$F, REGEXMATCH('OLT DOWN Tickets'!$AB:$AB, ""(?i)""&TRIM(D6)), 'OLT DOWN Tickets'!$L:$L=""OLT UPLINK DOWN""), 1), """")"),"") | M6: =IFERROR(__xludf.DUMMYFUNCTION("IFERROR(INDEX(FILTER('OLT DOWN Tickets'!$F:$F, REGEXMATCH('OLT DOWN Tickets'!$AB:$AB, ""(?i)""&TRIM(D6)), 'OLT DOWN Tickets'!$L:$L=""OLT SERVICE DEGRADATION""), 1), """") "),"") | N6: FALSE | O6: FALSE | P6: FALSE | Q6: FALSE
B7: APAYAO | C7: FLORA | D7: FAY001-OLT-01 | E7: =NOT(OR(F7, G7, H7, I7)) -> TRUE | F7: =COUNTIFS('OLT DOWN Tickets'!$AB:$AB, "*" & D7 & "*", 'OLT DOWN Tickets'!$L:$L, "OLT DOWN") > 0 -> FALSE | G7: =COUNTIFS('OLT DOWN Tickets'!$AB:$AB, "*" & D7 & "*", 'OLT DOWN Tickets'!$L:$L, "OLT UPLINK LOW POWER") > 0 -> FALSE | H7: =COUNTIFS('OLT DOWN Tickets'!$AB:$AB, "*" & D7 & "*", 'OLT DOWN Tickets'!$L:$L, "OLT UPLINK DOWN") > 0 -> FALSE | I7: =COUNTIFS('OLT DOWN Tickets'!$AB:$AB, "*" & D7 & "*", 'OLT DOWN Tickets'!$L:$L, "OLT SERVICE DEGRADATION") > 0 -> FALSE | J7: =IFERROR(__xludf.DUMMYFUNCTION("IFERROR(INDEX(FILTER('OLT DOWN Tickets'!$F:$F, REGEXMATCH('OLT DOWN Tickets'!$AB:$AB, ""(?i)""&TRIM(D7)), 'OLT DOWN Tickets'!$L:$L=""OLT DOWN""), 1), """")"),"") | K7: =IFERROR(__xludf.DUMMYFUNCTION("IFERROR(INDEX(FILTER('OLT DOWN Tickets'!$F:$F, REGEXMATCH('OLT DOWN Tickets'!$AB:$AB, ""(?i)""&TRIM(D7)), 'OLT DOWN Tickets'!$L:$L=""OLT UPLINK LOW POWER""), 1), """")"),"") | L7: =IFERROR(__xludf.DUMMYFUNCTION("IFERROR(INDEX(FILTER('OLT DOWN Tickets'!$F:$F, REGEXMATCH('OLT DOWN Tickets'!$AB:$AB, ""(?i)""&TRIM(D7)), 'OLT DOWN Tickets'!$L:$L=""OLT UPLINK DOWN""), 1), """")"),"") | M7: =IFERROR(__xludf.DUMMYFUNCTION("IFERROR(INDEX(FILTER('OLT DOWN Tickets'!$F:$F, REGEXMATCH('OLT DOWN Tickets'!$AB:$AB, ""(?i)""&TRIM(D7)), 'OLT DOWN Tickets'!$L:$L=""OLT SERVICE DEGRADATION""), 1), """") "),"") | N7: FALSE | O7: FALSE | P7: FALSE | Q7: FALSE
B8: APAYAO | C8: LUNA | D8: LAY001-OLT-01 | E8: =NOT(OR(F8, G8, H8, I8)) -> TRUE | F8: =COUNTIFS('OLT DOWN Tickets'!$AB:$AB, "*" & D8 & "*", 'OLT DOWN Tickets'!$L:$L, "OLT DOWN") > 0 -> FALSE | G8: =COUNTIFS('OLT DOWN Tickets'!$AB:$AB, "*" & D8 & "*", 'OLT DOWN Tickets'!$L:$L, "OLT UPLINK LOW POWER") > 0 -> FALSE | H8: =COUNTIFS('OLT DOWN Tickets'!$AB:$AB, "*" & D8 & "*", 'OLT DOWN Tickets'!$L:$L, "OLT UPLINK DOWN") > 0 -> FALSE | I8: =COUNTIFS('OLT DOWN Tickets'!$AB:$AB, "*" & D8 & "*", 'OLT DOWN Tickets'!$L:$L, "OLT SERVICE DEGRADATION") > 0 -> FALSE | J8: =IFERROR(__xludf.DUMMYFUNCTION("IFERROR(INDEX(FILTER('OLT DOWN Tickets'!$F:$F, REGEXMATCH('OLT DOWN Tickets'!$AB:$AB, ""(?i)""&TRIM(D8)), 'OLT DOWN Tickets'!$L:$L=""OLT DOWN""), 1), """")"),"") | K8: =IFERROR(__xludf.DUMMYFUNCTION("IFERROR(INDEX(FILTER('OLT DOWN Tickets'!$F:$F, REGEXMATCH('OLT DOWN Tickets'!$AB:$AB, ""(?i)""&TRIM(D8)), 'OLT DOWN Tickets'!$L:$L=""OLT UPLINK LOW POWER""), 1), """")"),"") | L8: =IFERROR(__xludf.DUMMYFUNCTION("IFERROR(INDEX(FILTER('OLT DOWN Tickets'!$F:$F, REGEXMATCH('OLT DOWN Tickets'!$AB:$AB, ""(?i)""&TRIM(D8)), 'OLT DOWN Tickets'!$L:$L=""OLT UPLINK DOWN""), 1), """")"),"") | M8: =IFERROR(__xludf.DUMMYFUNCTION("IFERROR(INDEX(FILTER('OLT DOWN Tickets'!$F:$F, REGEXMATCH('OLT DOWN Tickets'!$AB:$AB, ""(?i)""&TRIM(D8)), 'OLT DOWN Tickets'!$L:$L=""OLT SERVICE DEGRADATION""), 1), """") "),"") | N8: FALSE | O8: FALSE | P8: FALSE | Q8: FALSE
B9: APAYAO | C9: PUDTOL | D9: PLY001-OLT-01 | E9: =NOT(OR(F9, G9, H9, I9)) -> TRUE | F9: =COUNTIFS('OLT DOWN Tickets'!$AB:$AB, "*" & D9 & "*", 'OLT DOWN Tickets'!$L:$L, "OLT DOWN") > 0 -> FALSE | G9: =COUNTIFS('OLT DOWN Tickets'!$AB:$AB, "*" & D9 & "*", 'OLT DOWN Tickets'!$L:$L, "OLT UPLINK LOW POWER") > 0 -> FALSE | H9: =COUNTIFS('OLT DOWN Tickets'!$AB:$AB, "*" & D9 & "*", 'OLT DOWN Tickets'!$L:$L, "OLT UPLINK DOWN") > 0 -> FALSE | I9: =COUNTIFS('OLT DOWN Tickets'!$AB:$AB, "*" & D9 & "*", 'OLT DOWN Tickets'!$L:$L, "OLT SERVICE DEGRADATION") > 0 -> FALSE | J9: =IFERROR(__xludf.DUMMYFUNCTION("IFERROR(INDEX(FILTER('OLT DOWN Tickets'!$F:$F, REGEXMATCH('OLT DOWN Tickets'!$AB:$AB, ""(?i)""&TRIM(D9)), 'OLT DOWN Tickets'!$L:$L=""OLT DOWN""), 1), """")"),"") | K9: =IFERROR(__xludf.DUMMYFUNCTION("IFERROR(INDEX(FILTER('OLT DOWN Tickets'!$F:$F, REGEXMATCH('OLT DOWN Tickets'!$AB:$AB, ""(?i)""&TRIM(D9)), 'OLT DOWN Tickets'!$L:$L=""OLT UPLINK LOW POWER""), 1), """")"),"") | L9: =IFERROR(__xludf.DUMMYFUNCTION("IFERROR(INDEX(FILTER('OLT DOWN Tickets'!$F:$F, REGEXMATCH('OLT DOWN Tickets'!$AB:$AB, ""(?i)""&TRIM(D9)), 'OLT DOWN Tickets'!$L:$L=""OLT UPLINK DOWN""), 1), """")"),"") | M9: =IFERROR(__xludf.DUMMYFUNCTION("IFERROR(INDEX(FILTER('OLT DOWN Tickets'!$F:$F, REGEXMATCH('OLT DOWN Tickets'!$AB:$AB, ""(?i)""&TRIM(D9)), 'OLT DOWN Tickets'!$L:$L=""OLT SERVICE DEGRADATION""), 1), """") "),"") | N9: FALSE | O9: FALSE | P9: FALSE | Q9: FALSE
B10: APAYAO | C10: SANTA MARCELA | D10: SMY001-OLT-01 | E10: =NOT(OR(F10, G10, H10, I10)) -> TRUE | F10: =COUNTIFS('OLT DOWN Tickets'!$AB:$AB, "*" & D10 & "*", 'OLT DOWN Tickets'!$L:$L, "OLT DOWN") > 0 -> FALSE | G10: =COUNTIFS('OLT DOWN Tickets'!$AB:$AB, "*" & D10 & "*", 'OLT DOWN Tickets'!$L:$L, "OLT UPLINK LOW POWER") > 0 -> FALSE | H10: =COUNTIFS('OLT DOWN Tickets'!$AB:$AB, "*" & D10 & "*", 'OLT DOWN Tickets'!$L:$L, "OLT UPLINK DOWN") > 0 -> FALSE | I10: =COUNTIFS('OLT DOWN Tickets'!$AB:$AB, "*" & D10 & "*", 'OLT DOWN Tickets'!$L:$L, "OLT SERVICE DEGRADATION") > 0 -> FALSE | J10: =IFERROR(__xludf.DUMMYFUNCTION("IFERROR(INDEX(FILTER('OLT DOWN Tickets'!$F:$F, REGEXMATCH('OLT DOWN Tickets'!$AB:$AB, ""(?i)""&TRIM(D10)), 'OLT DOWN Tickets'!$L:$L=""OLT DOWN""), 1), """")"),"") | K10: =IFERROR(__xludf.DUMMYFUNCTION("IFERROR(INDEX(FILTER('OLT DOWN Tickets'!$F:$F, REGEXMATCH('OLT DOWN Tickets'!$AB:$AB, ""(?i)""&TRIM(D10)), 'OLT DOWN Tickets'!$L:$L=""OLT UPLINK LOW POWER""), 1), """")"),"") | L10: =IFERROR(__xludf.DUMMYFUNCTION("IFERROR(INDEX(FILTER('OLT DOWN Tickets'!$F:$F, REGEXMATCH('OLT DOWN Tickets'!$AB:$AB, ""(?i)""&TRIM(D10)), 'OLT DOWN Tickets'!$L:$L=""OLT UPLINK DOWN""), 1), """")"),"") | M10: =IFERROR(__xludf.DUMMYFUNCTION("IFERROR(INDEX(FILTER('OLT DOWN Tickets'!$F:$F, REGEXMATCH('OLT DOWN Tickets'!$AB:$AB, ""(?i)""&TRIM(D10)), 'OLT DOWN Tickets'!$L:$L=""OLT SERVICE DEGRADATION""), 1), """") "),"") | N10: FALSE | O10: FALSE | P10: FALSE | Q10: FALSE
B11: AURORA | C11: BALER | D11: BLA001-OLT-01 | E11: =NOT(OR(F11, G11, H11, I11)) -> TRUE | F11: =COUNTIFS('OLT DOWN Tickets'!$AB:$AB, "*" & D11 & "*", 'OLT DOWN Tickets'!$L:$L, "OLT DOWN") > 0 -> FALSE | G11: =COUNTIFS('OLT DOWN Tickets'!$AB:$AB, "*" & D11 & "*", 'OLT DOWN Tickets'!$L:$L, "OLT UPLINK LOW POWER") > 0 -> FALSE | H11: =COUNTIFS('OLT DOWN Tickets'!$AB:$AB, "*" & D11 & "*", 'OLT DOWN Tickets'!$L:$L, "OLT UPLINK DOWN") > 0 -> FALSE | I11: =COUNTIFS('OLT DOWN Tickets'!$AB:$AB, "*" & D11 & "*", 'OLT DOWN Tickets'!$L:$L, "OLT SERVICE DEGRADATION") > 0 -> FALSE | J11: =IFERROR(__xludf.DUMMYFUNCTION("IFERROR(INDEX(FILTER('OLT DOWN Tickets'!$F:$F, REGEXMATCH('OLT DOWN Tickets'!$AB:$AB, ""(?i)""&TRIM(D11)), 'OLT DOWN Tickets'!$L:$L=""OLT DOWN""), 1), """")"),"") | K11: =IFERROR(__xludf.DUMMYFUNCTION("IFERROR(INDEX(FILTER('OLT DOWN Tickets'!$F:$F, REGEXMATCH('OLT DOWN Tickets'!$AB:$AB, ""(?i)""&TRIM(D11)), 'OLT DOWN Tickets'!$L:$L=""OLT UPLINK LOW POWER""), 1), """")"),"") | L11: =IFERROR(__xludf.DUMMYFUNCTION("IFERROR(INDEX(FILTER('OLT DOWN Tickets'!$F:$F, REGEXMATCH('OLT DOWN Tickets'!$AB:$AB, ""(?i)""&TRIM(D11)), 'OLT DOWN Tickets'!$L:$L=""OLT UPLINK DOWN""), 1), """")"),"") | M11: =IFERROR(__xludf.DUMMYFUNCTION("IFERROR(INDEX(FILTER('OLT DOWN Tickets'!$F:$F, REGEXMATCH('OLT DOWN Tickets'!$AB:$AB, ""(?i)""&TRIM(D11)), 'OLT DOWN Tickets'!$L:$L=""OLT SERVICE DEGRADATION""), 1), """") "),"") | N11: FALSE | O11: FALSE | P11: FALSE | Q11: FALSE
B12: AURORA | C12: CASIGURAN | D12: CSA002-OLT-01 | E12: =NOT(OR(F12, G12, H12, I12)) -> TRUE | F12: =COUNTIFS('OLT DOWN Tickets'!$AB:$AB, "*" & D12 & "*", 'OLT DOWN Tickets'!$L:$L, "OLT DOWN") > 0 -> FALSE | G12: =COUNTIFS('OLT DOWN Tickets'!$AB:$AB, "*" & D12 & "*", 'OLT DOWN Tickets'!$L:$L, "OLT UPLINK LOW POWER") > 0 -> FALSE | H12: =COUNTIFS('OLT DOWN Tickets'!$AB:$AB, "*" & D12 & "*", 'OLT DOWN Tickets'!$L:$L, "OLT UPLINK DOWN") > 0 -> FALSE | I12: =COUNTIFS('OLT DOWN Tickets'!$AB:$AB, "*" & D12 & "*", 'OLT DOWN Tickets'!$L:$L, "OLT SERVICE DEGRADATION") > 0 -> FALSE | J12: =IFERROR(__xludf.DUMMYFUNCTION("IFERROR(INDEX(FILTER('OLT DOWN Tickets'!$F:$F, REGEXMATCH('OLT DOWN Tickets'!$AB:$AB, ""(?i)""&TRIM(D12)), 'OLT DOWN Tickets'!$L:$L=""OLT DOWN""), 1), """")"),"") | K12: =IFERROR(__xludf.DUMMYFUNCTION("IFERROR(INDEX(FILTER('OLT DOWN Tickets'!$F:$F, REGEXMATCH('OLT DOWN Tickets'!$AB:$AB, ""(?i)""&TRIM(D12)), 'OLT DOWN Tickets'!$L:$L=""OLT UPLINK LOW POWER""), 1), """")"),"") | L12: =IFERROR(__xludf.DUMMYFUNCTION("IFERROR(INDEX(FILTER('OLT DOWN Tickets'!$F:$F, REGEXMATCH('OLT DOWN Tickets'!$AB:$AB, ""(?i)""&TRIM(D12)), 'OLT DOWN Tickets'!$L:$L=""OLT UPLINK DOWN""), 1), """")"),"") | M12: =IFERROR(__xludf.DUMMYFUNCTION("IFERROR(INDEX(FILTER('OLT DOWN Tickets'!$F:$F, REGEXMATCH('OLT DOWN Tickets'!$AB:$AB, ""(?i)""&TRIM(D12)), 'OLT DOWN Tickets'!$L:$L=""OLT SERVICE DEGRADATION""), 1), """") "),"") | N12: FALSE | O12: FALSE | P12: FALSE | Q12: FALSE
B13: AURORA | C13: CASIGURAN | D13: CSA001-OLT-01 | E13: =NOT(OR(F13, G13, H13, I13)) -> TRUE | F13: =COUNTIFS('OLT DOWN Tickets'!$AB:$AB, "*" & D13 & "*", 'OLT DOWN Tickets'!$L:$L, "OLT DOWN") > 0 -> FALSE | G13: =COUNTIFS('OLT DOWN Tickets'!$AB:$AB, "*" & D13 & "*", 'OLT DOWN Tickets'!$L:$L, "OLT UPLINK LOW POWER") > 0 -> FALSE | H13: =COUNTIFS('OLT DOWN Tickets'!$AB:$AB, "*" & D13 & "*", 'OLT DOWN Tickets'!$L:$L, "OLT UPLINK DOWN") > 0 -> FALSE | I13: =COUNTIFS('OLT DOWN Tickets'!$AB:$AB, "*" & D13 & "*", 'OLT DOWN Tickets'!$L:$L, "OLT SERVICE DEGRADATION") > 0 -> FALSE | J13: =IFERROR(__xludf.DUMMYFUNCTION("IFERROR(INDEX(FILTER('OLT DOWN Tickets'!$F:$F, REGEXMATCH('OLT DOWN Tickets'!$AB:$AB, ""(?i)""&TRIM(D13)), 'OLT DOWN Tickets'!$L:$L=""OLT DOWN""), 1), """")"),"") | K13: =IFERROR(__xludf.DUMMYFUNCTION("IFERROR(INDEX(FILTER('OLT DOWN Tickets'!$F:$F, REGEXMATCH('OLT DOWN Tickets'!$AB:$AB, ""(?i)""&TRIM(D13)), 'OLT DOWN Tickets'!$L:$L=""OLT UPLINK LOW POWER""), 1), """")"),"") | L13: =IFERROR(__xludf.DUMMYFUNCTION("IFERROR(INDEX(FILTER('OLT DOWN Tickets'!$F:$F, REGEXMATCH('OLT DOWN Tickets'!$AB:$AB, ""(?i)""&TRIM(D13)), 'OLT DOWN Tickets'!$L:$L=""OLT UPLINK DOWN""), 1), """")"),"") | M13: =IFERROR(__xludf.DUMMYFUNCTION("IFERROR(INDEX(FILTER('OLT DOWN Tickets'!$F:$F, REGEXMATCH('OLT DOWN Tickets'!$AB:$AB, ""(?i)""&TRIM(D13)), 'OLT DOWN Tickets'!$L:$L=""OLT SERVICE DEGRADATION""), 1), """") "),"") | N13: FALSE | O13: FALSE | P13: FALSE | Q13: FALSE
B14: AURORA | C14: DILASAG | D14: DLA001-OLT-01 | E14: =NOT(OR(F14, G14, H14, I14)) -> TRUE | F14: =COUNTIFS('OLT DOWN Tickets'!$AB:$AB, "*" & D14 & "*", 'OLT DOWN Tickets'!$L:$L, "OLT DOWN") > 0 -> FALSE | G14: =COUNTIFS('OLT DOWN Tickets'!$AB:$AB, "*" & D14 & "*", 'OLT DOWN Tickets'!$L:$L, "OLT UPLINK LOW POWER") > 0 -> FALSE | H14: =COUNTIFS('OLT DOWN Tickets'!$AB:$AB, "*" & D14 & "*", 'OLT DOWN Tickets'!$L:$L, "OLT UPLINK DOWN") > 0 -> FALSE | I14: =COUNTIFS('OLT DOWN Tickets'!$AB:$AB, "*" & D14 & "*", 'OLT DOWN Tickets'!$L:$L, "OLT SERVICE DEGRADATION") > 0 -> FALSE | J14: =IFERROR(__xludf.DUMMYFUNCTION("IFERROR(INDEX(FILTER('OLT DOWN Tickets'!$F:$F, REGEXMATCH('OLT DOWN Tickets'!$AB:$AB, ""(?i)""&TRIM(D14)), 'OLT DOWN Tickets'!$L:$L=""OLT DOWN""), 1), """")"),"") | K14: =IFERROR(__xludf.DUMMYFUNCTION("IFERROR(INDEX(FILTER('OLT DOWN Tickets'!$F:$F, REGEXMATCH('OLT DOWN Tickets'!$AB:$AB, ""(?i)""&TRIM(D14)), 'OLT DOWN Tickets'!$L:$L=""OLT UPLINK LOW POWER""), 1), """")"),"") | L14: =IFERROR(__xludf.DUMMYFUNCTION("IFERROR(INDEX(FILTER('OLT DOWN Tickets'!$F:$F, REGEXMATCH('OLT DOWN Tickets'!$AB:$AB, ""(?i)""&TRIM(D14)), 'OLT DOWN Tickets'!$L:$L=""OLT UPLINK DOWN""), 1), """")"),"") | M14: =IFERROR(__xludf.DUMMYFUNCTION("IFERROR(INDEX(FILTER('OLT DOWN Tickets'!$F:$F, REGEXMATCH('OLT DOWN Tickets'!$AB:$AB, ""(?i)""&TRIM(D14)), 'OLT DOWN Tickets'!$L:$L=""OLT SERVICE DEGRADATION""), 1), """") "),"") | N14: FALSE | O14: FALSE | P14: FALSE | Q14: FALSE
B15: AURORA | C15: DINALUNGAN | D15: DNA001-OLT-01 | E15: =NOT(OR(F15, G15, H15, I15)) -> TRUE | F15: =COUNTIFS('OLT DOWN Tickets'!$AB:$AB, "*" & D15 & "*", 'OLT DOWN Tickets'!$L:$L, "OLT DOWN") > 0 -> FALSE | G15: =COUNTIFS('OLT DOWN Tickets'!$AB:$AB, "*" & D15 & "*", 'OLT DOWN Tickets'!$L:$L, "OLT UPLINK LOW POWER") > 0 -> FALSE | H15: =COUNTIFS('OLT DOWN Tickets'!$AB:$AB, "*" & D15 & "*", 'OLT DOWN Tickets'!$L:$L, "OLT UPLINK DOWN") > 0 -> FALSE | I15: =COUNTIFS('OLT DOWN Tickets'!$AB:$AB, "*" & D15 & "*", 'OLT DOWN Tickets'!$L:$L, "OLT SERVICE DEGRADATION") > 0 -> FALSE | J15: =IFERROR(__xludf.DUMMYFUNCTION("IFERROR(INDEX(FILTER('OLT DOWN Tickets'!$F:$F, REGEXMATCH('OLT DOWN Tickets'!$AB:$AB, ""(?i)""&TRIM(D15)), 'OLT DOWN Tickets'!$L:$L=""OLT DOWN""), 1), """")"),"") | K15: =IFERROR(__xludf.DUMMYFUNCTION("IFERROR(INDEX(FILTER('OLT DOWN Tickets'!$F:$F, REGEXMATCH('OLT DOWN Tickets'!$AB:$AB, ""(?i)""&TRIM(D15)), 'OLT DOWN Tickets'!$L:$L=""OLT UPLINK LOW POWER""), 1), """")"),"") | L15: =IFERROR(__xludf.DUMMYFUNCTION("IFERROR(INDEX(FILTER('OLT DOWN Tickets'!$F:$F, REGEXMATCH('OLT DOWN Tickets'!$AB:$AB, ""(?i)""&TRIM(D15)), 'OLT DOWN Tickets'!$L:$L=""OLT UPLINK DOWN""), 1), """")"),"") | M15: =IFERROR(__xludf.DUMMYFUNCTION("IFERROR(INDEX(FILTER('OLT DOWN Tickets'!$F:$F, REGEXMATCH('OLT DOWN Tickets'!$AB:$AB, ""(?i)""&TRIM(D15)), 'OLT DOWN Tickets'!$L:$L=""OLT SERVICE DEGRADATION""), 1), """") "),"") | N15: FALSE | O15: FALSE | P15: FALSE | Q15: FALSE
B16: AURORA | C16: DINGALAN | D16: DGA001-OLT- 01 | E16: =NOT(OR(F16, G16, H16, I16)) -> TRUE | F16: =COUNTIFS('OLT DOWN Tickets'!$AB:$AB, "*" & D16 & "*", 'OLT DOWN Tickets'!$L:$L, "OLT DOWN") > 0 -> FALSE | G16: =COUNTIFS('OLT DOWN Tickets'!$AB:$AB, "*" & D16 & "*", 'OLT DOWN Tickets'!$L:$L, "OLT UPLINK LOW POWER") > 0 -> FALSE | H16: =COUNTIFS('OLT DOWN Tickets'!$AB:$AB, "*" & D16 & "*", 'OLT DOWN Tickets'!$L:$L, "OLT UPLINK DOWN") > 0 -> FALSE | I16: =COUNTIFS('OLT DOWN Tickets'!$AB:$AB, "*" & D16 & "*", 'OLT DOWN Tickets'!$L:$L, "OLT SERVICE DEGRADATION") > 0 -> FALSE | J16: =IFERROR(__xludf.DUMMYFUNCTION("IFERROR(INDEX(FILTER('OLT DOWN Tickets'!$F:$F, REGEXMATCH('OLT DOWN Tickets'!$AB:$AB, ""(?i)""&TRIM(D16)), 'OLT DOWN Tickets'!$L:$L=""OLT DOWN""), 1), """")"),"") | K16: =IFERROR(__xludf.DUMMYFUNCTION("IFERROR(INDEX(FILTER('OLT DOWN Tickets'!$F:$F, REGEXMATCH('OLT DOWN Tickets'!$AB:$AB, ""(?i)""&TRIM(D16)), 'OLT DOWN Tickets'!$L:$L=""OLT UPLINK LOW POWER""), 1), """")"),"") | L16: =IFERROR(__xludf.DUMMYFUNCTION("IFERROR(INDEX(FILTER('OLT DOWN Tickets'!$F:$F, REGEXMATCH('OLT DOWN Tickets'!$AB:$AB, ""(?i)""&TRIM(D16)), 'OLT DOWN Tickets'!$L:$L=""OLT UPLINK DOWN""), 1), """")"),"") | M16: =IFERROR(__xludf.DUMMYFUNCTION("IFERROR(INDEX(FILTER('OLT DOWN Tickets'!$F:$F, REGEXMATCH('OLT DOWN Tickets'!$AB:$AB, ""(?i)""&TRIM(D16)), 'OLT DOWN Tickets'!$L:$L=""OLT SERVICE DEGRADATION""), 1), """") "),"") | N16: FALSE | O16: FALSE | P16: FALSE | Q16: FALSE
B17: AURORA | C17: DINGALAN | D17: DGA001-OLT-01 | E17: =NOT(OR(F17, G17, H17, I17)) -> TRUE | F17: =COUNTIFS('OLT DOWN Tickets'!$AB:$AB, "*" & D17 & "*", 'OLT DOWN Tickets'!$L:$L, "OLT DOWN") > 0 -> FALSE | G17: =COUNTIFS('OLT DOWN Tickets'!$AB:$AB, "*" & D17 & "*", 'OLT DOWN Tickets'!$L:$L, "OLT UPLINK LOW POWER") > 0 -> FALSE | H17: =COUNTIFS('OLT DOWN Tickets'!$AB:$AB, "*" & D17 & "*", 'OLT DOWN Tickets'!$L:$L, "OLT UPLINK DOWN") > 0 -> FALSE | I17: =COUNTIFS('OLT DOWN Tickets'!$AB:$AB, "*" & D17 & "*", 'OLT DOWN Tickets'!$L:$L, "OLT SERVICE DEGRADATION") > 0 -> FALSE | J17: =IFERROR(__xludf.DUMMYFUNCTION("IFERROR(INDEX(FILTER('OLT DOWN Tickets'!$F:$F, REGEXMATCH('OLT DOWN Tickets'!$AB:$AB, ""(?i)""&TRIM(D17)), 'OLT DOWN Tickets'!$L:$L=""OLT DOWN""), 1), """")"),"") | K17: =IFERROR(__xludf.DUMMYFUNCTION("IFERROR(INDEX(FILTER('OLT DOWN Tickets'!$F:$F, REGEXMATCH('OLT DOWN Tickets'!$AB:$AB, ""(?i)""&TRIM(D17)), 'OLT DOWN Tickets'!$L:$L=""OLT UPLINK LOW POWER""), 1), """")"),"") | L17: =IFERROR(__xludf.DUMMYFUNCTION("IFERROR(INDEX(FILTER('OLT DOWN Tickets'!$F:$F, REGEXMATCH('OLT DOWN Tickets'!$AB:$AB, ""(?i)""&TRIM(D17)), 'OLT DOWN Tickets'!$L:$L=""OLT UPLINK DOWN""), 1), """")"),"") | M17: =IFERROR(__xludf.DUMMYFUNCTION("IFERROR(INDEX(FILTER('OLT DOWN Tickets'!$F:$F, REGEXMATCH('OLT DOWN Tickets'!$AB:$AB, ""(?i)""&TRIM(D17)), 'OLT DOWN Tickets'!$L:$L=""OLT SERVICE DEGRADATION""), 1), """") "),"") | N17: FALSE | O17: FALSE | P17: FALSE | Q17: FALSE
B18: AURORA | C18: DIPACULAO | D18: DPA001-OLT-01 | E18: =NOT(OR(F18, G18, H18, I18)) -> TRUE | F18: =COUNTIFS('OLT DOWN Tickets'!$AB:$AB, "*" & D18 & "*", 'OLT DOWN Tickets'!$L:$L, "OLT DOWN") > 0 -> FALSE | G18: =COUNTIFS('OLT DOWN Tickets'!$AB:$AB, "*" & D18 & "*", 'OLT DOWN Tickets'!$L:$L, "OLT UPLINK LOW POWER") > 0 -> FALSE | H18: =COUNTIFS('OLT DOWN Tickets'!$AB:$AB, "*" & D18 & "*", 'OLT DOWN Tickets'!$L:$L, "OLT UPLINK DOWN") > 0 -> FALSE | I18: =COUNTIFS('OLT DOWN Tickets'!$AB:$AB, "*" & D18 & "*", 'OLT DOWN Tickets'!$L:$L, "OLT SERVICE DEGRADATION") > 0 -> FALSE | J18: =IFERROR(__xludf.DUMMYFUNCTION("IFERROR(INDEX(FILTER('OLT DOWN Tickets'!$F:$F, REGEXMATCH('OLT DOWN Tickets'!$AB:$AB, ""(?i)""&TRIM(D18)), 'OLT DOWN Tickets'!$L:$L=""OLT DOWN""), 1), """")"),"") | K18: =IFERROR(__xludf.DUMMYFUNCTION("IFERROR(INDEX(FILTER('OLT DOWN Tickets'!$F:$F, REGEXMATCH('OLT DOWN Tickets'!$AB:$AB, ""(?i)""&TRIM(D18)), 'OLT DOWN Tickets'!$L:$L=""OLT UPLINK LOW POWER""), 1), """")"),"") | L18: =IFERROR(__xludf.DUMMYFUNCTION("IFERROR(INDEX(FILTER('OLT DOWN Tickets'!$F:$F, REGEXMATCH('OLT DOWN Tickets'!$AB:$AB, ""(?i)""&TRIM(D18)), 'OLT DOWN Tickets'!$L:$L=""OLT UPLINK DOWN""), 1), """")"),"") | M18: =IFERROR(__xludf.DUMMYFUNCTION("IFERROR(INDEX(FILTER('OLT DOWN Tickets'!$F:$F, REGEXMATCH('OLT DOWN Tickets'!$AB:$AB, ""(?i)""&TRIM(D18)), 'OLT DOWN Tickets'!$L:$L=""OLT SERVICE DEGRADATION""), 1), """") "),"") | N18: FALSE | O18: FALSE | P18: FALSE | Q18: FALSE
B19: AURORA | C19: DIPACULAO | D19: DPA002-OLT-01 | E19: =NOT(OR(F19, G19, H19, I19)) -> TRUE | F19: =COUNTIFS('OLT DOWN Tickets'!$AB:$AB, "*" & D19 & "*", 'OLT DOWN Tickets'!$L:$L, "OLT DOWN") > 0 -> FALSE | G19: =COUNTIFS('OLT DOWN Tickets'!$AB:$AB, "*" & D19 & "*", 'OLT DOWN Tickets'!$L:$L, "OLT UPLINK LOW POWER") > 0 -> FALSE | H19: =COUNTIFS('OLT DOWN Tickets'!$AB:$AB, "*" & D19 & "*", 'OLT DOWN Tickets'!$L:$L, "OLT UPLINK DOWN") > 0 -> FALSE | I19: =COUNTIFS('OLT DOWN Tickets'!$AB:$AB, "*" & D19 & "*", 'OLT DOWN Tickets'!$L:$L, "OLT SERVICE DEGRADATION") > 0 -> FALSE | J19: =IFERROR(__xludf.DUMMYFUNCTION("IFERROR(INDEX(FILTER('OLT DOWN Tickets'!$F:$F, REGEXMATCH('OLT DOWN Tickets'!$AB:$AB, ""(?i)""&TRIM(D19)), 'OLT DOWN Tickets'!$L:$L=""OLT DOWN""), 1), """")"),"") | K19: =IFERROR(__xludf.DUMMYFUNCTION("IFERROR(INDEX(FILTER('OLT DOWN Tickets'!$F:$F, REGEXMATCH('OLT DOWN Tickets'!$AB:$AB, ""(?i)""&TRIM(D19)), 'OLT DOWN Tickets'!$L:$L=""OLT UPLINK LOW POWER""), 1), """")"),"") | L19: =IFERROR(__xludf.DUMMYFUNCTION("IFERROR(INDEX(FILTER('OLT DOWN Tickets'!$F:$F, REGEXMATCH('OLT DOWN Tickets'!$AB:$AB, ""(?i)""&TRIM(D19)), 'OLT DOWN Tickets'!$L:$L=""OLT UPLINK DOWN""), 1), """")"),"") | M19: =IFERROR(__xludf.DUMMYFUNCTION("IFERROR(INDEX(FILTER('OLT DOWN Tickets'!$F:$F, REGEXMATCH('OLT DOWN Tickets'!$AB:$AB, ""(?i)""&TRIM(D19)), 'OLT DOWN Tickets'!$L:$L=""OLT SERVICE DEGRADATION""), 1), """") "),"") | N19: FALSE | O19: FALSE | P19: FALSE | Q19: FALSE
B20: AURORA | C20: MARIA AURORA | D20: MAA001-OLT-01 | E20: =NOT(OR(F20, G20, H20, I20)) -> TRUE | F20: =COUNTIFS('OLT DOWN Tickets'!$AB:$AB, "*" & D20 & "*", 'OLT DOWN Tickets'!$L:$L, "OLT DOWN") > 0 -> FALSE | G20: =COUNTIFS('OLT DOWN Tickets'!$AB:$AB, "*" & D20 & "*", 'OLT DOWN Tickets'!$L:$L, "OLT UPLINK LOW POWER") > 0 -> FALSE | H20: =COUNTIFS('OLT DOWN Tickets'!$AB:$AB, "*" & D20 & "*", 'OLT DOWN Tickets'!$L:$L, "OLT UPLINK DOWN") > 0 -> FALSE | I20: =COUNTIFS('OLT DOWN Tickets'!$AB:$AB, "*" & D20 & "*", 'OLT DOWN Tickets'!$L:$L, "OLT SERVICE DEGRADATION") > 0 -> FALSE | J20: =IFERROR(__xludf.DUMMYFUNCTION("IFERROR(INDEX(FILTER('OLT DOWN Tickets'!$F:$F, REGEXMATCH('OLT DOWN Tickets'!$AB:$AB, ""(?i)""&TRIM(D20)), 'OLT DOWN Tickets'!$L:$L=""OLT DOWN""), 1), """")"),"") | K20: =IFERROR(__xludf.DUMMYFUNCTION("IFERROR(INDEX(FILTER('OLT DOWN Tickets'!$F:$F, REGEXMATCH('OLT DOWN Tickets'!$AB:$AB, ""(?i)""&TRIM(D20)), 'OLT DOWN Tickets'!$L:$L=""OLT UPLINK LOW POWER""), 1), """")"),"") | L20: =IFERROR(__xludf.DUMMYFUNCTION("IFERROR(INDEX(FILTER('OLT DOWN Tickets'!$F:$F, REGEXMATCH('OLT DOWN Tickets'!$AB:$AB, ""(?i)""&TRIM(D20)), 'OLT DOWN Tickets'!$L:$L=""OLT UPLINK DOWN""), 1), """")"),"") | M20: =IFERROR(__xludf.DUMMYFUNCTION("IFERROR(INDEX(FILTER('OLT DOWN Tickets'!$F:$F, REGEXMATCH('OLT DOWN Tickets'!$AB:$AB, ""(?i)""&TRIM(D20)), 'OLT DOWN Tickets'!$L:$L=""OLT SERVICE DEGRADATION""), 1), """") "),"") | N20: FALSE | O20: FALSE | P20: FALSE | Q20: FALSE
B21: AURORA | C21: SAN LUIS | D21: SLA001-OLT-01 | E21: =NOT(OR(F21, G21, H21, I21)) -> TRUE | F21: =COUNTIFS('OLT DOWN Tickets'!$AB:$AB, "*" & D21 & "*", 'OLT DOWN Tickets'!$L:$L, "OLT DOWN") > 0 -> FALSE | G21: =COUNTIFS('OLT DOWN Tickets'!$AB:$AB, "*" & D21 & "*", 'OLT DOWN Tickets'!$L:$L, "OLT UPLINK LOW POWER") > 0 -> FALSE | H21: =COUNTIFS('OLT DOWN Tickets'!$AB:$AB, "*" & D21 & "*", 'OLT DOWN Tickets'!$L:$L, "OLT UPLINK DOWN") > 0 -> FALSE | I21: =COUNTIFS('OLT DOWN Tickets'!$AB:$AB, "*" & D21 & "*", 'OLT DOWN Tickets'!$L:$L, "OLT SERVICE DEGRADATION") > 0 -> FALSE | J21: =IFERROR(__xludf.DUMMYFUNCTION("IFERROR(INDEX(FILTER('OLT DOWN Tickets'!$F:$F, REGEXMATCH('OLT DOWN Tickets'!$AB:$AB, ""(?i)""&TRIM(D21)), 'OLT DOWN Tickets'!$L:$L=""OLT DOWN""), 1), """")"),"") | K21: =IFERROR(__xludf.DUMMYFUNCTION("IFERROR(INDEX(FILTER('OLT DOWN Tickets'!$F:$F, REGEXMATCH('OLT DOWN Tickets'!$AB:$AB, ""(?i)""&TRIM(D21)), 'OLT DOWN Tickets'!$L:$L=""OLT UPLINK LOW POWER""), 1), """")"),"") | L21: =IFERROR(__xludf.DUMMYFUNCTION("IFERROR(INDEX(FILTER('OLT DOWN Tickets'!$F:$F, REGEXMATCH('OLT DOWN Tickets'!$AB:$AB, ""(?i)""&TRIM(D21)), 'OLT DOWN Tickets'!$L:$L=""OLT UPLINK DOWN""), 1), """")"),"") | M21: =IFERROR(__xludf.DUMMYFUNCTION("IFERROR(INDEX(FILTER('OLT DOWN Tickets'!$F:$F, REGEXMATCH('OLT DOWN Tickets'!$AB:$AB, ""(?i)""&TRIM(D21)), 'OLT DOWN Tickets'!$L:$L=""OLT SERVICE DEGRADATION""), 1), """") "),"") | N21: FALSE | O21: FALSE | P21: FALSE | Q21: FALSE
B22: AURORA | C22: SAN LUIS | D22: SLA001-OLT-02 | E22: =NOT(OR(F22, G22, H22, I22)) -> TRUE | F22: =COUNTIFS('OLT DOWN Tickets'!$AB:$AB, "*" & D22 & "*", 'OLT DOWN Tickets'!$L:$L, "OLT DOWN") > 0 -> FALSE | G22: =COUNTIFS('OLT DOWN Tickets'!$AB:$AB, "*" & D22 & "*", 'OLT DOWN Tickets'!$L:$L, "OLT UPLINK LOW POWER") > 0 -> FALSE | H22: =COUNTIFS('OLT DOWN Tickets'!$AB:$AB, "*" & D22 & "*", 'OLT DOWN Tickets'!$L:$L, "OLT UPLINK DOWN") > 0 -> FALSE | I22: =COUNTIFS('OLT DOWN Tickets'!$AB:$AB, "*" & D22 & "*", 'OLT DOWN Tickets'!$L:$L, "OLT SERVICE DEGRADATION") > 0 -> FALSE | J22: =IFERROR(__xludf.DUMMYFUNCTION("IFERROR(INDEX(FILTER('OLT DOWN Tickets'!$F:$F, REGEXMATCH('OLT DOWN Tickets'!$AB:$AB, ""(?i)""&TRIM(D22)), 'OLT DOWN Tickets'!$L:$L=""OLT DOWN""), 1), """")"),"") | K22: =IFERROR(__xludf.DUMMYFUNCTION("IFERROR(INDEX(FILTER('OLT DOWN Tickets'!$F:$F, REGEXMATCH('OLT DOWN Tickets'!$AB:$AB, ""(?i)""&TRIM(D22)), 'OLT DOWN Tickets'!$L:$L=""OLT UPLINK LOW POWER""), 1), """")"),"") | L22: =IFERROR(__xludf.DUMMYFUNCTION("IFERROR(INDEX(FILTER('OLT DOWN Tickets'!$F:$F, REGEXMATCH('OLT DOWN Tickets'!$AB:$AB, ""(?i)""&TRIM(D22)), 'OLT DOWN Tickets'!$L:$L=""OLT UPLINK DOWN""), 1), """")"),"") | M22: =IFERROR(__xludf.DUMMYFUNCTION("IFERROR(INDEX(FILTER('OLT DOWN Tickets'!$F:$F, REGEXMATCH('OLT DOWN Tickets'!$AB:$AB, ""(?i)""&TRIM(D22)), 'OLT DOWN Tickets'!$L:$L=""OLT SERVICE DEGRADATION""), 1), """") "),"") | N22: FALSE | O22: FALSE | P22: FALSE | Q22: FALSE
B23: BENGUET | C23: ATOK | D23: ATB001-OLT-01 | E23: =NOT(OR(F23, G23, H23, I23)) -> TRUE | F23: =COUNTIFS('OLT DOWN Tickets'!$AB:$AB, "*" & D23 & "*", 'OLT DOWN Tickets'!$L:$L, "OLT DOWN") > 0 -> FALSE | G23: =COUNTIFS('OLT DOWN Tickets'!$AB:$AB, "*" & D23 & "*", 'OLT DOWN Tickets'!$L:$L, "OLT UPLINK LOW POWER") > 0 -> FALSE | H23: =COUNTIFS('OLT DOWN Tickets'!$AB:$AB, "*" & D23 & "*", 'OLT DOWN Tickets'!$L:$L, "OLT UPLINK DOWN") > 0 -> FALSE | I23: =COUNTIFS('OLT DOWN Tickets'!$AB:$AB, "*" & D23 & "*", 'OLT DOWN Tickets'!$L:$L, "OLT SERVICE DEGRADATION") > 0 -> FALSE | J23: =IFERROR(__xludf.DUMMYFUNCTION("IFERROR(INDEX(FILTER('OLT DOWN Tickets'!$F:$F, REGEXMATCH('OLT DOWN Tickets'!$AB:$AB, ""(?i)""&TRIM(D23)), 'OLT DOWN Tickets'!$L:$L=""OLT DOWN""), 1), """")"),"") | K23: =IFERROR(__xludf.DUMMYFUNCTION("IFERROR(INDEX(FILTER('OLT DOWN Tickets'!$F:$F, REGEXMATCH('OLT DOWN Tickets'!$AB:$AB, ""(?i)""&TRIM(D23)), 'OLT DOWN Tickets'!$L:$L=""OLT UPLINK LOW POWER""), 1), """")"),"") | L23: =IFERROR(__xludf.DUMMYFUNCTION("IFERROR(INDEX(FILTER('OLT DOWN Tickets'!$F:$F, REGEXMATCH('OLT DOWN Tickets'!$AB:$AB, ""(?i)""&TRIM(D23)), 'OLT DOWN Tickets'!$L:$L=""OLT UPLINK DOWN""), 1), """")"),"") | M23: =IFERROR(__xludf.DUMMYFUNCTION("IFERROR(INDEX(FILTER('OLT DOWN Tickets'!$F:$F, REGEXMATCH('OLT DOWN Tickets'!$AB:$AB, ""(?i)""&TRIM(D23)), 'OLT DOWN Tickets'!$L:$L=""OLT SERVICE DEGRADATION""), 1), """") "),"") | N23: FALSE | O23: FALSE | P23: FALSE | Q23: FALSE
B24: BENGUET | C24: ATOK | D24: ATB002-OLT-01 | E24: =NOT(OR(F24, G24, H24, I24)) -> TRUE | F24: =COUNTIFS('OLT DOWN Tickets'!$AB:$AB, "*" & D24 & "*", 'OLT DOWN Tickets'!$L:$L, "OLT DOWN") > 0 -> FALSE | G24: =COUNTIFS('OLT DOWN Tickets'!$AB:$AB, "*" & D24 & "*", 'OLT DOWN Tickets'!$L:$L, "OLT UPLINK LOW POWER") > 0 -> FALSE | H24: =COUNTIFS('OLT DOWN Tickets'!$AB:$AB, "*" & D24 & "*", 'OLT DOWN Tickets'!$L:$L, "OLT UPLINK DOWN") > 0 -> FALSE | I24: =COUNTIFS('OLT DOWN Tickets'!$AB:$AB, "*" & D24 & "*", 'OLT DOWN Tickets'!$L:$L, "OLT SERVICE DEGRADATION") > 0 -> FALSE | J24: =IFERROR(__xludf.DUMMYFUNCTION("IFERROR(INDEX(FILTER('OLT DOWN Tickets'!$F:$F, REGEXMATCH('OLT DOWN Tickets'!$AB:$AB, ""(?i)""&TRIM(D24)), 'OLT DOWN Tickets'!$L:$L=""OLT DOWN""), 1), """")"),"") | K24: =IFERROR(__xludf.DUMMYFUNCTION("IFERROR(INDEX(FILTER('OLT DOWN Tickets'!$F:$F, REGEXMATCH('OLT DOWN Tickets'!$AB:$AB, ""(?i)""&TRIM(D24)), 'OLT DOWN Tickets'!$L:$L=""OLT UPLINK LOW POWER""), 1), """")"),"") | L24: =IFERROR(__xludf.DUMMYFUNCTION("IFERROR(INDEX(FILTER('OLT DOWN Tickets'!$F:$F, REGEXMATCH('OLT DOWN Tickets'!$AB:$AB, ""(?i)""&TRIM(D24)), 'OLT DOWN Tickets'!$L:$L=""OLT UPLINK DOWN""), 1), """")"),"") | M24: =IFERROR(__xludf.DUMMYFUNCTION("IFERROR(INDEX(FILTER('OLT DOWN Tickets'!$F:$F, REGEXMATCH('OLT DOWN Tickets'!$AB:$AB, ""(?i)""&TRIM(D24)), 'OLT DOWN Tickets'!$L:$L=""OLT SERVICE DEGRADATION""), 1), """") "),"") | N24: FALSE | O24: FALSE | P24: FALSE | Q24: FALSE
